2025-10-07 07:59:42 | ERROR | {"request_id": "14c8a165-5657-429c-8446-f7be4c273562", "timestamp": "2025-10-07T07:59:42.264439", "client_ip": "10.200.0.1", "endpoint": "/api/execute-query", "error_type": "HTTPException", "error_message": "403: Column KRBLF is restricted. Permission request #36 created.", "error_code": "HTTP_403", "additional_context": {"original_detail": "Column KRBLF is restricted. Permission request #36 created."}}
2025-10-07 07:59:42 | ERROR | {"request_id": "14c8a165-5657-429c-8446-f7be4c273562", "timestamp": "2025-10-07T07:59:42.278255", "client_ip": "10.200.0.1", "endpoint": "/api/execute-query", "error_type": "TypeError", "error_message": "Object of type datetime is not JSON serializable", "error_code": "INTERNAL_ERROR", "additional_context": {"traceback": "  + Exception Group Traceback (most recent call last):\n  |   File \"C:\\service-gateway\\venv\\Lib\\site-packages\\starlette\\_utils.py\", line 79, in collapse_excgroups\n  |     yield\n  |   File \"C:\\service-gateway\\venv\\Lib\\site-packages\\starlette\\middleware\\base.py\", line 183, in __call__\n  |     async with anyio.create_task_group() as task_group:\n  |                ~~~~~~~~~~~~~~~~~~~~~~~^^\n  |   File \"C:\\service-gateway\\venv\\Lib\\site-packages\\anyio\\_backends\\_asyncio.py\", line 781, in __aexit__\n  |     raise BaseExceptionGroup(\n  |         \"unhandled errors in a TaskGroup\", self._exceptions\n  |     ) from None\n  | ExceptionGroup: unhandled errors in a TaskGroup (1 sub-exception)\n  +-+---------------- 1 ----------------\n    | Traceback (most recent call last):\n    |   File \"C:\\service-gateway\\venv\\Lib\\site-packages\\starlette\\middleware\\errors.py\", line 164, in __call__\n    |     await self.app(scope, receive, _send)\n    |   File \"C:\\service-gateway\\venv\\Lib\\site-packages\\starlette\\middleware\\cors.py\", line 85, in __call__\n    |     await self.app(scope, receive, send)\n    |   File \"C:\\service-gateway\\venv\\Lib\\site-packages\\starlette\\middleware\\base.py\", line 182, in __call__\n    |     with recv_stream, send_stream, collapse_excgroups():\n    |                                    ~~~~~~~~~~~~~~~~~~^^\n    |   File \"C:\\Python313\\Lib\\contextlib.py\", line 162, in __exit__\n    |     self.gen.throw(value)\n    |     ~~~~~~~~~~~~~~^^^^^^^\n    |   File \"C:\\service-gateway\\venv\\Lib\\site-packages\\starlette\\_utils.py\", line 85, in collapse_excgroups\n    |     raise exc\n    |   File \"C:\\service-gateway\\venv\\Lib\\site-packages\\starlette\\middleware\\base.py\", line 184, in __call__\n    |     response = await self.dispatch_func(request, call_next)\n    |                ^^^^^^^^^^^^^^^^^^^^^^^^^^^^^^^^^^^^^^^^^^^^\n    |   File \"C:\\service-gateway\\utils\\request_middleware.py\", line 15, in dispatch\n    |     response = await call_next(request)\n    |                ^^^^^^^^^^^^^^^^^^^^^^^^\n    |   File \"C:\\service-gateway\\venv\\Lib\\site-packages\\starlette\\middleware\\base.py\", line 159, in call_next\n    |     raise app_exc\n    |   File \"C:\\service-gateway\\venv\\Lib\\site-packages\\starlette\\middleware\\base.py\", line 144, in coro\n    |     await self.app(scope, receive_or_disconnect, send_no_error)\n    |   File \"C:\\service-gateway\\venv\\Lib\\site-packages\\starlette\\middleware\\exceptions.py\", line 63, in __call__\n    |     await wrap_app_handling_exceptions(self.app, conn)(scope, receive, send)\n    |   File \"C:\\service-gateway\\venv\\Lib\\site-packages\\starlette\\_exception_handler.py\", line 53, in wrapped_app\n    |     raise exc\n    |   File \"C:\\service-gateway\\venv\\Lib\\site-packages\\starlette\\_exception_handler.py\", line 42, in wrapped_app\n    |     await app(scope, receive, sender)\n    |   File \"C:\\service-gateway\\venv\\Lib\\site-packages\\starlette\\routing.py\", line 716, in __call__\n    |     await self.middleware_stack(scope, receive, send)\n    |   File \"C:\\service-gateway\\venv\\Lib\\site-packages\\starlette\\routing.py\", line 736, in app\n    |     await route.handle(scope, receive, send)\n    |   File \"C:\\service-gateway\\venv\\Lib\\site-packages\\starlette\\routing.py\", line 290, in handle\n    |     await self.app(scope, receive, send)\n    |   File \"C:\\service-gateway\\venv\\Lib\\site-packages\\starlette\\routing.py\", line 78, in app\n    |     await wrap_app_handling_exceptions(app, request)(scope, receive, send)\n    |   File \"C:\\service-gateway\\venv\\Lib\\site-packages\\starlette\\_exception_handler.py\", line 59, in wrapped_app\n    |     response = await handler(conn, exc)\n    |                ^^^^^^^^^^^^^^^^^^^^^^^^\n    |   File \"C:\\service-gateway\\utils\\error_handler.py\", line 59, in http_exception_handler\n    |     return JSONResponse(\n    |         status_code=exc.status_code,\n    |     ...<5 lines>...\n    |         ).dict()\n    |     )\n    |   File \"C:\\service-gateway\\venv\\Lib\\site-packages\\starlette\\responses.py\", line 190, in __init__\n    |     super().__init__(content, status_code, headers, media_type, background)\n    |     ~~~~~~~~~~~~~~~~^^^^^^^^^^^^^^^^^^^^^^^^^^^^^^^^^^^^^^^^^^^^^^^^^^^^^^^\n    |   File \"C:\\service-gateway\\venv\\Lib\\site-packages\\starlette\\responses.py\", line 47, in __init__\n    |     self.body = self.render(content)\n    |                 ~~~~~~~~~~~^^^^^^^^^\n    |   File \"C:\\service-gateway\\venv\\Lib\\site-packages\\starlette\\responses.py\", line 193, in render\n    |     return json.dumps(\n    |            ~~~~~~~~~~^\n    |         content,\n    |         ^^^^^^^^\n    |     ...<3 lines>...\n    |         separators=(\",\", \":\"),\n    |         ^^^^^^^^^^^^^^^^^^^^^^\n    |     ).encode(\"utf-8\")\n    |     ^\n    |   File \"C:\\Python313\\Lib\\json\\__init__.py\", line 238, in dumps\n    |     **kw).encode(obj)\n    |           ~~~~~~^^^^^\n    |   File \"C:\\Python313\\Lib\\json\\encoder.py\", line 200, in encode\n    |     chunks = self.iterencode(o, _one_shot=True)\n    |   File \"C:\\Python313\\Lib\\json\\encoder.py\", line 261, in iterencode\n    |     return _iterencode(o, 0)\n    |   File \"C:\\Python313\\Lib\\json\\encoder.py\", line 180, in default\n    |     raise TypeError(f'Object of type {o.__class__.__name__} '\n    |                     f'is not JSON serializable')\n    | TypeError: Object of type datetime is not JSON serializable\n    +------------------------------------\n\nDuring handling of the above exception, another exception occurred:\n\nTraceback (most recent call last):\n  File \"C:\\service-gateway\\venv\\Lib\\site-packages\\starlette\\middleware\\errors.py\", line 164, in __call__\n    await self.app(scope, receive, _send)\n  File \"C:\\service-gateway\\venv\\Lib\\site-packages\\starlette\\middleware\\cors.py\", line 85, in __call__\n    await self.app(scope, receive, send)\n  File \"C:\\service-gateway\\venv\\Lib\\site-packages\\starlette\\middleware\\base.py\", line 182, in __call__\n    with recv_stream, send_stream, collapse_excgroups():\n                                   ~~~~~~~~~~~~~~~~~~^^\n  File \"C:\\Python313\\Lib\\contextlib.py\", line 162, in __exit__\n    self.gen.throw(value)\n    ~~~~~~~~~~~~~~^^^^^^^\n  File \"C:\\service-gateway\\venv\\Lib\\site-packages\\starlette\\_utils.py\", line 85, in collapse_excgroups\n    raise exc\n  File \"C:\\service-gateway\\venv\\Lib\\site-packages\\starlette\\middleware\\base.py\", line 184, in __call__\n    response = await self.dispatch_func(request, call_next)\n               ^^^^^^^^^^^^^^^^^^^^^^^^^^^^^^^^^^^^^^^^^^^^\n  File \"C:\\service-gateway\\utils\\request_middleware.py\", line 15, in dispatch\n    response = await call_next(request)\n               ^^^^^^^^^^^^^^^^^^^^^^^^\n  File \"C:\\service-gateway\\venv\\Lib\\site-packages\\starlette\\middleware\\base.py\", line 159, in call_next\n    raise app_exc\n  File \"C:\\service-gateway\\venv\\Lib\\site-packages\\starlette\\middleware\\base.py\", line 144, in coro\n    await self.app(scope, receive_or_disconnect, send_no_error)\n  File \"C:\\service-gateway\\venv\\Lib\\site-packages\\starlette\\middleware\\exceptions.py\", line 63, in __call__\n    await wrap_app_handling_exceptions(self.app, conn)(scope, receive, send)\n  File \"C:\\service-gateway\\venv\\Lib\\site-packages\\starlette\\_exception_handler.py\", line 53, in wrapped_app\n    raise exc\n  File \"C:\\service-gateway\\venv\\Lib\\site-packages\\starlette\\_exception_handler.py\", line 42, in wrapped_app\n    await app(scope, receive, sender)\n  File \"C:\\service-gateway\\venv\\Lib\\site-packages\\starlette\\routing.py\", line 716, in __call__\n    await self.middleware_stack(scope, receive, send)\n  File \"C:\\service-gateway\\venv\\Lib\\site-packages\\starlette\\routing.py\", line 736, in app\n    await route.handle(scope, receive, send)\n  File \"C:\\service-gateway\\venv\\Lib\\site-packages\\starlette\\routing.py\", line 290, in handle\n    await self.app(scope, receive, send)\n  File \"C:\\service-gateway\\venv\\Lib\\site-packages\\starlette\\routing.py\", line 78, in app\n    await wrap_app_handling_exceptions(app, request)(scope, receive, send)\n  File \"C:\\service-gateway\\venv\\Lib\\site-packages\\starlette\\_exception_handler.py\", line 59, in wrapped_app\n    response = await handler(conn, exc)\n               ^^^^^^^^^^^^^^^^^^^^^^^^\n  File \"C:\\service-gateway\\utils\\error_handler.py\", line 59, in http_exception_handler\n    return JSONResponse(\n        status_code=exc.status_code,\n    ...<5 lines>...\n        ).dict()\n    )\n  File \"C:\\service-gateway\\venv\\Lib\\site-packages\\starlette\\responses.py\", line 190, in __init__\n    super().__init__(content, status_code, headers, media_type, background)\n    ~~~~~~~~~~~~~~~~^^^^^^^^^^^^^^^^^^^^^^^^^^^^^^^^^^^^^^^^^^^^^^^^^^^^^^^\n  File \"C:\\service-gateway\\venv\\Lib\\site-packages\\starlette\\responses.py\", line 47, in __init__\n    self.body = self.render(content)\n                ~~~~~~~~~~~^^^^^^^^^\n  File \"C:\\service-gateway\\venv\\Lib\\site-packages\\starlette\\responses.py\", line 193, in render\n    return json.dumps(\n           ~~~~~~~~~~^\n        content,\n        ^^^^^^^^\n    ...<3 lines>...\n        separators=(\",\", \":\"),\n        ^^^^^^^^^^^^^^^^^^^^^^\n    ).encode(\"utf-8\")\n    ^\n  File \"C:\\Python313\\Lib\\json\\__init__.py\", line 238, in dumps\n    **kw).encode(obj)\n          ~~~~~~^^^^^\n  File \"C:\\Python313\\Lib\\json\\encoder.py\", line 200, in encode\n    chunks = self.iterencode(o, _one_shot=True)\n  File \"C:\\Python313\\Lib\\json\\encoder.py\", line 261, in iterencode\n    return _iterencode(o, 0)\n  File \"C:\\Python313\\Lib\\json\\encoder.py\", line 180, in default\n    raise TypeError(f'Object of type {o.__class__.__name__} '\n                    f'is not JSON serializable')\nTypeError: Object of type datetime is not JSON serializable\n", "exception_type": "TypeError"}}
2025-10-07 08:22:00 | ERROR | {"request_id": "284b802c-d662-47ef-9aea-175ef16dd454", "timestamp": "2025-10-07T08:22:00.936357", "client_ip": "10.200.0.1", "endpoint": "/api/execute-query", "error_type": "HTTPException", "error_message": "403: Column OHBLF is restricted. Permission request #37 created.", "error_code": "HTTP_403", "additional_context": {"original_detail": "Column OHBLF is restricted. Permission request #37 created."}}
2025-10-07 08:23:18 | ERROR | {"request_id": "659fd3a8-528a-42c9-ae34-c35445890fa4", "timestamp": "2025-10-07T08:23:18.548925", "client_ip": "10.200.0.1", "endpoint": "/api/execute-query", "error_type": "HTTPException", "error_message": "403: Access denied to table DCPO.ORKORDRR. Permission request #39 created.", "error_code": "HTTP_403", "additional_context": {"original_detail": "Access denied to table DCPO.ORKORDRR. Permission request #39 created."}}
2025-10-07 08:24:23 | ERROR | {"request_id": "d7084b61-6f24-4021-9c37-50a3db557d9f", "timestamp": "2025-10-07T08:24:23.190536", "client_ip": "10.200.0.1", "endpoint": "/api/execute-query", "error_type": "HTTPException", "error_message": "403: Access denied to table DCPO.KRKFAKTR. Permission request #41 created.", "error_code": "HTTP_403", "additional_context": {"original_detail": "Access denied to table DCPO.KRKFAKTR. Permission request #41 created."}}
2025-10-07 08:27:29 | ERROR | {"request_id": "2202df7f-f670-433b-89fb-3c61c69777dd", "timestamp": "2025-10-07T08:27:29.588259", "client_ip": "10.200.0.1", "endpoint": "/api/execute-query", "error_type": "HTTPException", "error_message": "403: Column KRBLF is restricted. Permission request #43 created.", "error_code": "HTTP_403", "additional_context": {"original_detail": "Column KRBLF is restricted. Permission request #43 created."}}
2025-10-07 08:33:02 | ERROR | {"request_id": "8b917601-e767-46ba-b73a-9f2a60647c3b", "timestamp": "2025-10-07T08:33:02.074829", "client_ip": "10.200.0.1", "endpoint": "/api/execute-query", "error_type": "HTTPException", "error_message": "403: Access denied to table DCPO.ORKORDRR. Permission request #44 created.", "error_code": "HTTP_403", "additional_context": {"original_detail": "Access denied to table DCPO.ORKORDRR. Permission request #44 created."}}
2025-10-07 10:33:58 | ERROR | {"request_id": "93094fc7-c2b7-4731-a138-4abc7d21bd60", "timestamp": "2025-10-07T10:33:58.286975", "client_ip": "10.200.0.1", "endpoint": "/api/execute-query", "error_type": "HTTPException", "error_message": "403: Access denied to table DCPO.AHARTHUR. Permission request #47 created.", "error_code": "HTTP_403", "additional_context": {"original_detail": "Access denied to table DCPO.AHARTHUR. Permission request #47 created."}}
2025-10-07 10:49:51 | ERROR | {"request_id": "9ddd2791-8eaa-479b-9c2d-859fc4f5689b", "timestamp": "2025-10-07T10:49:51.051979", "client_ip": "10.200.0.1", "endpoint": "/api/execute-query", "error_type": "HTTPException", "error_message": "403: Access denied to table EGU.AYARINFR. Permission request #49 created.", "error_code": "HTTP_403", "additional_context": {"original_detail": "Access denied to table EGU.AYARINFR. Permission request #49 created."}}
2025-10-08 10:47:46 | ERROR | {"request_id": "2bdd58cb-b11c-4f67-a446-496ff8e98425", "timestamp": "2025-10-08T10:47:46.309603", "client_ip": "10.200.0.1", "endpoint": "/api/conversation/create-session", "error_type": "HTTPException", "error_message": "500: PersistentMemoryService.__init__() missing 1 required positional argument: 'connection_string'", "error_code": "HTTP_500", "additional_context": {"original_detail": "PersistentMemoryService.__init__() missing 1 required positional argument: 'connection_string'"}}
2025-10-08 10:47:46 | ERROR | {"request_id": "410379c9-a576-460f-87ff-ba39d31a40e1", "timestamp": "2025-10-08T10:47:46.465699", "client_ip": "10.200.0.1", "endpoint": "/api/conversation/get-messages/774c8fe4-2113-4484-a569-89d16140a769", "error_type": "HTTPException", "error_message": "500: PersistentMemoryService.__init__() missing 1 required positional argument: 'connection_string'", "error_code": "HTTP_500", "additional_context": {"original_detail": "PersistentMemoryService.__init__() missing 1 required positional argument: 'connection_string'"}}
2025-10-08 10:47:46 | ERROR | {"request_id": "58ccdf50-ee60-46d2-ba91-1a6d949d2df7", "timestamp": "2025-10-08T10:47:46.748733", "client_ip": "10.200.0.1", "endpoint": "/api/conversation/get-messages/774c8fe4-2113-4484-a569-89d16140a769", "error_type": "HTTPException", "error_message": "500: PersistentMemoryService.__init__() missing 1 required positional argument: 'connection_string'", "error_code": "HTTP_500", "additional_context": {"original_detail": "PersistentMemoryService.__init__() missing 1 required positional argument: 'connection_string'"}}
2025-10-08 10:47:57 | ERROR | {"request_id": "84fe08ca-db48-43d5-9783-27504cdc1e85", "timestamp": "2025-10-08T10:47:57.738203", "client_ip": "10.200.0.1", "endpoint": "/api/conversation/get-messages/774c8fe4-2113-4484-a569-89d16140a769", "error_type": "HTTPException", "error_message": "500: PersistentMemoryService.__init__() missing 1 required positional argument: 'connection_string'", "error_code": "HTTP_500", "additional_context": {"original_detail": "PersistentMemoryService.__init__() missing 1 required positional argument: 'connection_string'"}}
2025-10-08 10:47:57 | ERROR | {"request_id": "62f904bd-31b9-4e1e-afa7-62ea94b1f081", "timestamp": "2025-10-08T10:47:57.904431", "client_ip": "10.200.0.1", "endpoint": "/api/conversation/save-message", "error_type": "HTTPException", "error_message": "500: PersistentMemoryService.__init__() missing 1 required positional argument: 'connection_string'", "error_code": "HTTP_500", "additional_context": {"original_detail": "PersistentMemoryService.__init__() missing 1 required positional argument: 'connection_string'"}}
2025-10-08 10:48:05 | ERROR | {"request_id": "79c1c232-bc71-421d-80d9-4934eb969718", "timestamp": "2025-10-08T10:48:05.637395", "client_ip": "10.200.0.1", "endpoint": "/api/conversation/update-context", "error_type": "HTTPException", "error_message": "500: PersistentMemoryService.__init__() missing 1 required positional argument: 'connection_string'", "error_code": "HTTP_500", "additional_context": {"original_detail": "PersistentMemoryService.__init__() missing 1 required positional argument: 'connection_string'"}}
2025-10-08 10:48:05 | ERROR | {"request_id": "60ea6e63-22d7-408f-94ec-a5d9d71e7df4", "timestamp": "2025-10-08T10:48:05.792666", "client_ip": "10.200.0.1", "endpoint": "/api/conversation/save-message", "error_type": "HTTPException", "error_message": "500: PersistentMemoryService.__init__() missing 1 required positional argument: 'connection_string'", "error_code": "HTTP_500", "additional_context": {"original_detail": "PersistentMemoryService.__init__() missing 1 required positional argument: 'connection_string'"}}
2025-10-08 10:48:06 | ERROR | {"request_id": "02b9d917-fc36-4a4b-93f9-ae8ee2bad2b5", "timestamp": "2025-10-08T10:48:06.096472", "client_ip": "10.200.0.1", "endpoint": "/api/conversation/get-messages/774c8fe4-2113-4484-a569-89d16140a769", "error_type": "HTTPException", "error_message": "500: PersistentMemoryService.__init__() missing 1 required positional argument: 'connection_string'", "error_code": "HTTP_500", "additional_context": {"original_detail": "PersistentMemoryService.__init__() missing 1 required positional argument: 'connection_string'"}}
2025-10-08 10:48:12 | ERROR | {"request_id": "71b91dbf-9266-4290-8036-277997e2bee7", "timestamp": "2025-10-08T10:48:12.201781", "client_ip": "10.200.0.1", "endpoint": "/api/conversation/get-messages/774c8fe4-2113-4484-a569-89d16140a769", "error_type": "HTTPException", "error_message": "500: PersistentMemoryService.__init__() missing 1 required positional argument: 'connection_string'", "error_code": "HTTP_500", "additional_context": {"original_detail": "PersistentMemoryService.__init__() missing 1 required positional argument: 'connection_string'"}}
2025-10-08 10:48:12 | ERROR | {"request_id": "fee79e4b-fd0f-4ba5-ae21-7f269a7fd0d9", "timestamp": "2025-10-08T10:48:12.373851", "client_ip": "10.200.0.1", "endpoint": "/api/conversation/save-message", "error_type": "HTTPException", "error_message": "500: PersistentMemoryService.__init__() missing 1 required positional argument: 'connection_string'", "error_code": "HTTP_500", "additional_context": {"original_detail": "PersistentMemoryService.__init__() missing 1 required positional argument: 'connection_string'"}}
2025-10-08 10:48:20 | ERROR | {"request_id": "9908b8ed-8eb6-48ba-9e3d-dd8e3818c7e4", "timestamp": "2025-10-08T10:48:20.004047", "client_ip": "10.200.0.1", "endpoint": "/api/conversation/update-context", "error_type": "HTTPException", "error_message": "500: PersistentMemoryService.__init__() missing 1 required positional argument: 'connection_string'", "error_code": "HTTP_500", "additional_context": {"original_detail": "PersistentMemoryService.__init__() missing 1 required positional argument: 'connection_string'"}}
2025-10-08 10:48:20 | ERROR | {"request_id": "52b933bf-74e6-4ec7-9a53-4882500be891", "timestamp": "2025-10-08T10:48:20.157310", "client_ip": "10.200.0.1", "endpoint": "/api/conversation/save-message", "error_type": "HTTPException", "error_message": "500: PersistentMemoryService.__init__() missing 1 required positional argument: 'connection_string'", "error_code": "HTTP_500", "additional_context": {"original_detail": "PersistentMemoryService.__init__() missing 1 required positional argument: 'connection_string'"}}
2025-10-08 10:48:20 | ERROR | {"request_id": "5bc107db-0197-4067-9baf-6f82728a1bba", "timestamp": "2025-10-08T10:48:20.454637", "client_ip": "10.200.0.1", "endpoint": "/api/conversation/get-messages/774c8fe4-2113-4484-a569-89d16140a769", "error_type": "HTTPException", "error_message": "500: PersistentMemoryService.__init__() missing 1 required positional argument: 'connection_string'", "error_code": "HTTP_500", "additional_context": {"original_detail": "PersistentMemoryService.__init__() missing 1 required positional argument: 'connection_string'"}}
2025-10-08 10:53:22 | ERROR | {"request_id": "fd5dba2a-50ad-4d60-956a-fba4086f93d4", "timestamp": "2025-10-08T10:53:22.645000", "client_ip": "10.200.0.1", "endpoint": "/api/conversation/get-messages/774c8fe4-2113-4484-a569-89d16140a769", "error_type": "HTTPException", "error_message": "500: PersistentMemoryService.__init__() missing 1 required positional argument: 'connection_string'", "error_code": "HTTP_500", "additional_context": {"original_detail": "PersistentMemoryService.__init__() missing 1 required positional argument: 'connection_string'"}}
2025-10-08 10:53:22 | ERROR | {"request_id": "743c4217-f9af-40ae-94e6-f6f9ec5908a1", "timestamp": "2025-10-08T10:53:22.859815", "client_ip": "10.200.0.1", "endpoint": "/api/conversation/save-message", "error_type": "HTTPException", "error_message": "500: PersistentMemoryService.__init__() missing 1 required positional argument: 'connection_string'", "error_code": "HTTP_500", "additional_context": {"original_detail": "PersistentMemoryService.__init__() missing 1 required positional argument: 'connection_string'"}}
2025-10-08 10:53:29 | ERROR | {"request_id": "cfec1f15-0d1b-45a7-96f7-76e198b8de50", "timestamp": "2025-10-08T10:53:29.877826", "client_ip": "10.200.0.1", "endpoint": "/api/conversation/update-context", "error_type": "HTTPException", "error_message": "500: PersistentMemoryService.__init__() missing 1 required positional argument: 'connection_string'", "error_code": "HTTP_500", "additional_context": {"original_detail": "PersistentMemoryService.__init__() missing 1 required positional argument: 'connection_string'"}}
2025-10-08 10:53:30 | ERROR | {"request_id": "dc7b6c52-89d5-47bb-8d32-b97e38a70b82", "timestamp": "2025-10-08T10:53:30.071373", "client_ip": "10.200.0.1", "endpoint": "/api/conversation/save-message", "error_type": "HTTPException", "error_message": "500: PersistentMemoryService.__init__() missing 1 required positional argument: 'connection_string'", "error_code": "HTTP_500", "additional_context": {"original_detail": "PersistentMemoryService.__init__() missing 1 required positional argument: 'connection_string'"}}
2025-10-08 10:53:30 | ERROR | {"request_id": "b564bda6-0633-4185-b7af-b68436500525", "timestamp": "2025-10-08T10:53:30.409952", "client_ip": "10.200.0.1", "endpoint": "/api/conversation/get-messages/774c8fe4-2113-4484-a569-89d16140a769", "error_type": "HTTPException", "error_message": "500: PersistentMemoryService.__init__() missing 1 required positional argument: 'connection_string'", "error_code": "HTTP_500", "additional_context": {"original_detail": "PersistentMemoryService.__init__() missing 1 required positional argument: 'connection_string'"}}
2025-10-08 10:59:34 | ERROR | {"request_id": "459505c0-8ebe-4201-aff0-f2b401f626c1", "timestamp": "2025-10-08T10:59:34.690917", "client_ip": "10.200.0.1", "endpoint": "/api/conversation/get-messages/774c8fe4-2113-4484-a569-89d16140a769", "error_type": "HTTPException", "error_message": "500: 'PersistentMemoryService' object has no attribute 'get_session_messages'", "error_code": "HTTP_500", "additional_context": {"original_detail": "'PersistentMemoryService' object has no attribute 'get_session_messages'"}}
2025-10-08 10:59:34 | ERROR | {"request_id": "bcde6ee0-6e39-4c6f-86d9-7bcbfce3c81a", "timestamp": "2025-10-08T10:59:34.906052", "client_ip": "10.200.0.1", "endpoint": "/api/conversation/save-message", "error_type": "HTTPException", "error_message": "500: PersistentMemoryService.save_message() got an unexpected keyword argument 'message_content'", "error_code": "HTTP_500", "additional_context": {"original_detail": "PersistentMemoryService.save_message() got an unexpected keyword argument 'message_content'"}}
2025-10-08 10:59:40 | ERROR | {"request_id": "f6c919b4-5fbc-44a3-b708-713891f9dc6f", "timestamp": "2025-10-08T10:59:40.248553", "client_ip": "10.200.0.1", "endpoint": "/api/conversation/update-context", "error_type": "HTTPException", "error_message": "500: 'PersistentMemoryService' object has no attribute 'update_conversation_context'", "error_code": "HTTP_500", "additional_context": {"original_detail": "'PersistentMemoryService' object has no attribute 'update_conversation_context'"}}
2025-10-08 10:59:40 | ERROR | {"request_id": "e1073615-8165-4005-89cf-eb401e5acdf9", "timestamp": "2025-10-08T10:59:40.457444", "client_ip": "10.200.0.1", "endpoint": "/api/conversation/save-message", "error_type": "HTTPException", "error_message": "500: PersistentMemoryService.save_message() got an unexpected keyword argument 'message_content'", "error_code": "HTTP_500", "additional_context": {"original_detail": "PersistentMemoryService.save_message() got an unexpected keyword argument 'message_content'"}}
2025-10-08 10:59:40 | ERROR | {"request_id": "78047422-0099-4e43-a214-799dc5d3a9fa", "timestamp": "2025-10-08T10:59:40.797937", "client_ip": "10.200.0.1", "endpoint": "/api/conversation/get-messages/774c8fe4-2113-4484-a569-89d16140a769", "error_type": "HTTPException", "error_message": "500: 'PersistentMemoryService' object has no attribute 'get_session_messages'", "error_code": "HTTP_500", "additional_context": {"original_detail": "'PersistentMemoryService' object has no attribute 'get_session_messages'"}}
2025-10-08 11:00:24 | ERROR | {"request_id": "6c8cdb70-9bc1-4914-927b-484f443112c5", "timestamp": "2025-10-08T11:00:24.916467", "client_ip": "10.200.0.1", "endpoint": "/api/conversation/create-session", "error_type": "HTTPException", "error_message": "500: 'PersistentMemoryService' object has no attribute 'create_session'", "error_code": "HTTP_500", "additional_context": {"original_detail": "'PersistentMemoryService' object has no attribute 'create_session'"}}
2025-10-08 11:00:25 | ERROR | {"request_id": "5651774a-7900-47ce-9b48-ec9e00d4d963", "timestamp": "2025-10-08T11:00:25.125745", "client_ip": "10.200.0.1", "endpoint": "/api/conversation/get-messages/458233f3-9bd0-471b-b7f6-234f36afb3b4", "error_type": "HTTPException", "error_message": "500: 'PersistentMemoryService' object has no attribute 'get_session_messages'", "error_code": "HTTP_500", "additional_context": {"original_detail": "'PersistentMemoryService' object has no attribute 'get_session_messages'"}}
2025-10-08 11:00:25 | ERROR | {"request_id": "d3a9009e-8659-4a8d-9be4-0ae75a231b36", "timestamp": "2025-10-08T11:00:25.504000", "client_ip": "10.200.0.1", "endpoint": "/api/conversation/get-messages/458233f3-9bd0-471b-b7f6-234f36afb3b4", "error_type": "HTTPException", "error_message": "500: 'PersistentMemoryService' object has no attribute 'get_session_messages'", "error_code": "HTTP_500", "additional_context": {"original_detail": "'PersistentMemoryService' object has no attribute 'get_session_messages'"}}
2025-10-08 11:00:29 | ERROR | {"request_id": "9c612659-4b99-4b04-87fb-7db3915e7bc4", "timestamp": "2025-10-08T11:00:29.294153", "client_ip": "10.200.0.1", "endpoint": "/api/conversation/get-messages/458233f3-9bd0-471b-b7f6-234f36afb3b4", "error_type": "HTTPException", "error_message": "500: 'PersistentMemoryService' object has no attribute 'get_session_messages'", "error_code": "HTTP_500", "additional_context": {"original_detail": "'PersistentMemoryService' object has no attribute 'get_session_messages'"}}
2025-10-08 11:00:29 | ERROR | {"request_id": "111b27a2-9bdd-4aef-bae2-a4ecb7d0415d", "timestamp": "2025-10-08T11:00:29.508466", "client_ip": "10.200.0.1", "endpoint": "/api/conversation/save-message", "error_type": "HTTPException", "error_message": "500: PersistentMemoryService.save_message() got an unexpected keyword argument 'message_content'", "error_code": "HTTP_500", "additional_context": {"original_detail": "PersistentMemoryService.save_message() got an unexpected keyword argument 'message_content'"}}
2025-10-08 11:00:34 | ERROR | {"request_id": "0973016b-56ba-46ca-8900-21f4bc64502a", "timestamp": "2025-10-08T11:00:34.273247", "client_ip": "10.200.0.1", "endpoint": "/api/conversation/update-context", "error_type": "HTTPException", "error_message": "500: 'PersistentMemoryService' object has no attribute 'update_conversation_context'", "error_code": "HTTP_500", "additional_context": {"original_detail": "'PersistentMemoryService' object has no attribute 'update_conversation_context'"}}
2025-10-08 11:00:34 | ERROR | {"request_id": "f82100ce-040b-4f76-8633-88832a69ba5b", "timestamp": "2025-10-08T11:00:34.481648", "client_ip": "10.200.0.1", "endpoint": "/api/conversation/save-message", "error_type": "HTTPException", "error_message": "500: PersistentMemoryService.save_message() got an unexpected keyword argument 'message_content'", "error_code": "HTTP_500", "additional_context": {"original_detail": "PersistentMemoryService.save_message() got an unexpected keyword argument 'message_content'"}}
2025-10-08 11:00:34 | ERROR | {"request_id": "d2f0655c-0125-4153-a3ec-04e5e1e33b86", "timestamp": "2025-10-08T11:00:34.830290", "client_ip": "10.200.0.1", "endpoint": "/api/conversation/get-messages/458233f3-9bd0-471b-b7f6-234f36afb3b4", "error_type": "HTTPException", "error_message": "500: 'PersistentMemoryService' object has no attribute 'get_session_messages'", "error_code": "HTTP_500", "additional_context": {"original_detail": "'PersistentMemoryService' object has no attribute 'get_session_messages'"}}
2025-10-08 11:02:40 | ERROR | {"request_id": "3de54f56-1597-4b85-ae32-7912d34fb6fd", "timestamp": "2025-10-08T11:02:40.294804", "client_ip": "10.200.0.1", "endpoint": "/api/conversation/create-session", "error_type": "HTTPException", "error_message": "500: 'PersistentMemoryService' object has no attribute 'create_session'", "error_code": "HTTP_500", "additional_context": {"original_detail": "'PersistentMemoryService' object has no attribute 'create_session'"}}
2025-10-08 11:02:40 | ERROR | {"request_id": "65755613-d346-499b-a177-fb9a5c62f393", "timestamp": "2025-10-08T11:02:40.466365", "client_ip": "10.200.0.1", "endpoint": "/api/conversation/get-messages/b34bdfb1-e08c-4337-89ea-3dd39ef4ba22", "error_type": "HTTPException", "error_message": "500: 'PersistentMemoryService' object has no attribute 'get_session_messages'", "error_code": "HTTP_500", "additional_context": {"original_detail": "'PersistentMemoryService' object has no attribute 'get_session_messages'"}}
2025-10-08 11:02:40 | ERROR | {"request_id": "8a367b71-2bd4-4cff-a9d0-509af6fc520c", "timestamp": "2025-10-08T11:02:40.781830", "client_ip": "10.200.0.1", "endpoint": "/api/conversation/get-messages/b34bdfb1-e08c-4337-89ea-3dd39ef4ba22", "error_type": "HTTPException", "error_message": "500: 'PersistentMemoryService' object has no attribute 'get_session_messages'", "error_code": "HTTP_500", "additional_context": {"original_detail": "'PersistentMemoryService' object has no attribute 'get_session_messages'"}}
2025-10-08 13:19:43 | ERROR | {"request_id": "ba10771d-937e-49cf-bfbb-96df747dffe3", "timestamp": "2025-10-08T13:19:43.872784", "client_ip": "10.200.0.1", "endpoint": "/chat", "error_type": "HTTPException", "error_message": "404: Not Found", "error_code": "HTTP_404", "additional_context": {"original_detail": "Not Found"}}
2025-10-08 14:38:53 | ERROR | {"request_id": "4ad21565-3fc2-4e89-b7ad-71ec2229ea3c", "timestamp": "2025-10-08T14:38:53.656635", "client_ip": "10.200.0.2", "endpoint": "/", "error_type": "HTTPException", "error_message": "404: Not Found", "error_code": "HTTP_404", "additional_context": {"original_detail": "Not Found"}}
2025-10-08 14:38:53 | ERROR | {"request_id": "5abed9d0-d708-41c4-a653-9ef9ab99f68e", "timestamp": "2025-10-08T14:38:53.831576", "client_ip": "10.200.0.2", "endpoint": "/favicon.ico", "error_type": "HTTPException", "error_message": "404: Not Found", "error_code": "HTTP_404", "additional_context": {"original_detail": "Not Found"}}
2025-10-08 14:52:21 | ERROR | {"request_id": "e581d97b-f135-4625-a8b7-d9587b0cc206", "timestamp": "2025-10-08T14:52:21.780953", "client_ip": "10.200.0.2", "endpoint": "/", "error_type": "HTTPException", "error_message": "404: Not Found", "error_code": "HTTP_404", "additional_context": {"original_detail": "Not Found"}}
2025-10-08 14:53:39 | ERROR | {"request_id": "44002bbc-3e65-4745-b993-f754f8d9b807", "timestamp": "2025-10-08T14:53:39.213471", "client_ip": "10.200.0.2", "endpoint": "/", "error_type": "HTTPException", "error_message": "404: Not Found", "error_code": "HTTP_404", "additional_context": {"original_detail": "Not Found"}}
2025-10-09 15:11:15 | ERROR | {"request_id": "958f305a-9482-4b16-b983-be19b3a4c4b8", "timestamp": "2025-10-09T15:11:15.813873", "client_ip": "10.200.0.1", "endpoint": "/api/execute-query", "error_type": "HTTPException", "error_message": "403: Column KHKG\u00c4 is restricted. Permission request #51 created.", "error_code": "HTTP_403", "additional_context": {"original_detail": "Column KHKG\u00c4 is restricted. Permission request #51 created."}}
2025-10-09 15:11:46 | ERROR | {"request_id": "fe95c139-4ed9-4a91-8951-abcb4af2141c", "timestamp": "2025-10-09T15:11:46.660688", "client_ip": "10.200.0.1", "endpoint": "/api/execute-query", "error_type": "HTTPException", "error_message": "403: Column KHKG\u00c4 is restricted. Permission request #52 created.", "error_code": "HTTP_403", "additional_context": {"original_detail": "Column KHKG\u00c4 is restricted. Permission request #52 created."}}
2025-10-09 15:11:52 | ERROR | {"request_id": "1f66e991-d059-4d10-a3f2-58376f6d5d69", "timestamp": "2025-10-09T15:11:52.591539", "client_ip": "10.200.0.1", "endpoint": "/api/permission-requests/27/deny", "error_type": "RequestValidationError", "error_message": "[{'type': 'string_type', 'loc': ('body',), 'msg': 'Input should be a valid string', 'input': {'review_notes': 'o'}}]", "error_code": "VALIDATION_ERROR", "additional_context": {"validation_errors": [{"field": "", "message": "Input should be a valid string", "type": "string_type"}]}}
2025-10-09 15:11:52 | ERROR | {"request_id": "1f66e991-d059-4d10-a3f2-58376f6d5d69", "timestamp": "2025-10-09T15:11:52.797555", "client_ip": "10.200.0.1", "endpoint": "/api/permission-requests/27/deny", "error_type": "AttributeError", "error_message": "'RequestValidationError' object has no attribute 'status_code'", "error_code": "INTERNAL_ERROR", "additional_context": {"traceback": "  + Exception Group Traceback (most recent call last):\n  |   File \"C:\\service-gateway\\venv\\Lib\\site-packages\\starlette\\_utils.py\", line 79, in collapse_excgroups\n  |     yield\n  |   File \"C:\\service-gateway\\venv\\Lib\\site-packages\\starlette\\middleware\\base.py\", line 183, in __call__\n  |     async with anyio.create_task_group() as task_group:\n  |                ~~~~~~~~~~~~~~~~~~~~~~~^^\n  |   File \"C:\\service-gateway\\venv\\Lib\\site-packages\\anyio\\_backends\\_asyncio.py\", line 781, in __aexit__\n  |     raise BaseExceptionGroup(\n  |         \"unhandled errors in a TaskGroup\", self._exceptions\n  |     ) from None\n  | ExceptionGroup: unhandled errors in a TaskGroup (1 sub-exception)\n  +-+---------------- 1 ----------------\n    | Traceback (most recent call last):\n    |   File \"C:\\service-gateway\\venv\\Lib\\site-packages\\starlette\\middleware\\errors.py\", line 164, in __call__\n    |     await self.app(scope, receive, _send)\n    |   File \"C:\\service-gateway\\venv\\Lib\\site-packages\\starlette\\middleware\\cors.py\", line 85, in __call__\n    |     await self.app(scope, receive, send)\n    |   File \"C:\\service-gateway\\venv\\Lib\\site-packages\\starlette\\middleware\\base.py\", line 182, in __call__\n    |     with recv_stream, send_stream, collapse_excgroups():\n    |                                    ~~~~~~~~~~~~~~~~~~^^\n    |   File \"C:\\Python313\\Lib\\contextlib.py\", line 162, in __exit__\n    |     self.gen.throw(value)\n    |     ~~~~~~~~~~~~~~^^^^^^^\n    |   File \"C:\\service-gateway\\venv\\Lib\\site-packages\\starlette\\_utils.py\", line 85, in collapse_excgroups\n    |     raise exc\n    |   File \"C:\\service-gateway\\venv\\Lib\\site-packages\\starlette\\middleware\\base.py\", line 184, in __call__\n    |     response = await self.dispatch_func(request, call_next)\n    |                ^^^^^^^^^^^^^^^^^^^^^^^^^^^^^^^^^^^^^^^^^^^^\n    |   File \"C:\\service-gateway\\utils\\request_middleware.py\", line 15, in dispatch\n    |     response = await call_next(request)\n    |                ^^^^^^^^^^^^^^^^^^^^^^^^\n    |   File \"C:\\service-gateway\\venv\\Lib\\site-packages\\starlette\\middleware\\base.py\", line 159, in call_next\n    |     raise app_exc\n    |   File \"C:\\service-gateway\\venv\\Lib\\site-packages\\starlette\\middleware\\base.py\", line 144, in coro\n    |     await self.app(scope, receive_or_disconnect, send_no_error)\n    |   File \"C:\\service-gateway\\venv\\Lib\\site-packages\\starlette\\middleware\\exceptions.py\", line 63, in __call__\n    |     await wrap_app_handling_exceptions(self.app, conn)(scope, receive, send)\n    |   File \"C:\\service-gateway\\venv\\Lib\\site-packages\\starlette\\_exception_handler.py\", line 53, in wrapped_app\n    |     raise exc\n    |   File \"C:\\service-gateway\\venv\\Lib\\site-packages\\starlette\\_exception_handler.py\", line 42, in wrapped_app\n    |     await app(scope, receive, sender)\n    |   File \"C:\\service-gateway\\venv\\Lib\\site-packages\\starlette\\routing.py\", line 716, in __call__\n    |     await self.middleware_stack(scope, receive, send)\n    |   File \"C:\\service-gateway\\venv\\Lib\\site-packages\\starlette\\routing.py\", line 736, in app\n    |     await route.handle(scope, receive, send)\n    |   File \"C:\\service-gateway\\venv\\Lib\\site-packages\\starlette\\routing.py\", line 290, in handle\n    |     await self.app(scope, receive, send)\n    |   File \"C:\\service-gateway\\venv\\Lib\\site-packages\\starlette\\routing.py\", line 78, in app\n    |     await wrap_app_handling_exceptions(app, request)(scope, receive, send)\n    |   File \"C:\\service-gateway\\venv\\Lib\\site-packages\\starlette\\_exception_handler.py\", line 59, in wrapped_app\n    |     response = await handler(conn, exc)\n    |                ^^^^^^^^^^^^^^^^^^^^^^^^\n    |   File \"C:\\service-gateway\\utils\\error_handler.py\", line 100, in validation_exception_handler\n    |     status_code=exc.status_code,\n    |                 ^^^^^^^^^^^^^^^\n    | AttributeError: 'RequestValidationError' object has no attribute 'status_code'\n    +------------------------------------\n\nDuring handling of the above exception, another exception occurred:\n\nTraceback (most recent call last):\n  File \"C:\\service-gateway\\venv\\Lib\\site-packages\\starlette\\middleware\\errors.py\", line 164, in __call__\n    await self.app(scope, receive, _send)\n  File \"C:\\service-gateway\\venv\\Lib\\site-packages\\starlette\\middleware\\cors.py\", line 85, in __call__\n    await self.app(scope, receive, send)\n  File \"C:\\service-gateway\\venv\\Lib\\site-packages\\starlette\\middleware\\base.py\", line 182, in __call__\n    with recv_stream, send_stream, collapse_excgroups():\n                                   ~~~~~~~~~~~~~~~~~~^^\n  File \"C:\\Python313\\Lib\\contextlib.py\", line 162, in __exit__\n    self.gen.throw(value)\n    ~~~~~~~~~~~~~~^^^^^^^\n  File \"C:\\service-gateway\\venv\\Lib\\site-packages\\starlette\\_utils.py\", line 85, in collapse_excgroups\n    raise exc\n  File \"C:\\service-gateway\\venv\\Lib\\site-packages\\starlette\\middleware\\base.py\", line 184, in __call__\n    response = await self.dispatch_func(request, call_next)\n               ^^^^^^^^^^^^^^^^^^^^^^^^^^^^^^^^^^^^^^^^^^^^\n  File \"C:\\service-gateway\\utils\\request_middleware.py\", line 15, in dispatch\n    response = await call_next(request)\n               ^^^^^^^^^^^^^^^^^^^^^^^^\n  File \"C:\\service-gateway\\venv\\Lib\\site-packages\\starlette\\middleware\\base.py\", line 159, in call_next\n    raise app_exc\n  File \"C:\\service-gateway\\venv\\Lib\\site-packages\\starlette\\middleware\\base.py\", line 144, in coro\n    await self.app(scope, receive_or_disconnect, send_no_error)\n  File \"C:\\service-gateway\\venv\\Lib\\site-packages\\starlette\\middleware\\exceptions.py\", line 63, in __call__\n    await wrap_app_handling_exceptions(self.app, conn)(scope, receive, send)\n  File \"C:\\service-gateway\\venv\\Lib\\site-packages\\starlette\\_exception_handler.py\", line 53, in wrapped_app\n    raise exc\n  File \"C:\\service-gateway\\venv\\Lib\\site-packages\\starlette\\_exception_handler.py\", line 42, in wrapped_app\n    await app(scope, receive, sender)\n  File \"C:\\service-gateway\\venv\\Lib\\site-packages\\starlette\\routing.py\", line 716, in __call__\n    await self.middleware_stack(scope, receive, send)\n  File \"C:\\service-gateway\\venv\\Lib\\site-packages\\starlette\\routing.py\", line 736, in app\n    await route.handle(scope, receive, send)\n  File \"C:\\service-gateway\\venv\\Lib\\site-packages\\starlette\\routing.py\", line 290, in handle\n    await self.app(scope, receive, send)\n  File \"C:\\service-gateway\\venv\\Lib\\site-packages\\starlette\\routing.py\", line 78, in app\n    await wrap_app_handling_exceptions(app, request)(scope, receive, send)\n  File \"C:\\service-gateway\\venv\\Lib\\site-packages\\starlette\\_exception_handler.py\", line 59, in wrapped_app\n    response = await handler(conn, exc)\n               ^^^^^^^^^^^^^^^^^^^^^^^^\n  File \"C:\\service-gateway\\utils\\error_handler.py\", line 100, in validation_exception_handler\n    status_code=exc.status_code,\n                ^^^^^^^^^^^^^^^\nAttributeError: 'RequestValidationError' object has no attribute 'status_code'\n", "exception_type": "AttributeError"}}
2025-10-09 15:12:03 | ERROR | {"request_id": "63f9f12b-f47b-411d-9ef9-aaf1178778e6", "timestamp": "2025-10-09T15:12:03.152373", "client_ip": "10.200.0.1", "endpoint": "/api/permission-requests/27/deny", "error_type": "RequestValidationError", "error_message": "[{'type': 'string_type', 'loc': ('body',), 'msg': 'Input should be a valid string', 'input': {'review_notes': 'o'}}]", "error_code": "VALIDATION_ERROR", "additional_context": {"validation_errors": [{"field": "", "message": "Input should be a valid string", "type": "string_type"}]}}
2025-10-09 15:12:03 | ERROR | {"request_id": "63f9f12b-f47b-411d-9ef9-aaf1178778e6", "timestamp": "2025-10-09T15:12:03.158791", "client_ip": "10.200.0.1", "endpoint": "/api/permission-requests/27/deny", "error_type": "AttributeError", "error_message": "'RequestValidationError' object has no attribute 'status_code'", "error_code": "INTERNAL_ERROR", "additional_context": {"traceback": "  + Exception Group Traceback (most recent call last):\n  |   File \"C:\\service-gateway\\venv\\Lib\\site-packages\\starlette\\_utils.py\", line 79, in collapse_excgroups\n  |     yield\n  |   File \"C:\\service-gateway\\venv\\Lib\\site-packages\\starlette\\middleware\\base.py\", line 183, in __call__\n  |     async with anyio.create_task_group() as task_group:\n  |                ~~~~~~~~~~~~~~~~~~~~~~~^^\n  |   File \"C:\\service-gateway\\venv\\Lib\\site-packages\\anyio\\_backends\\_asyncio.py\", line 781, in __aexit__\n  |     raise BaseExceptionGroup(\n  |         \"unhandled errors in a TaskGroup\", self._exceptions\n  |     ) from None\n  | ExceptionGroup: unhandled errors in a TaskGroup (1 sub-exception)\n  +-+---------------- 1 ----------------\n    | Traceback (most recent call last):\n    |   File \"C:\\service-gateway\\venv\\Lib\\site-packages\\starlette\\middleware\\errors.py\", line 164, in __call__\n    |     await self.app(scope, receive, _send)\n    |   File \"C:\\service-gateway\\venv\\Lib\\site-packages\\starlette\\middleware\\cors.py\", line 85, in __call__\n    |     await self.app(scope, receive, send)\n    |   File \"C:\\service-gateway\\venv\\Lib\\site-packages\\starlette\\middleware\\base.py\", line 182, in __call__\n    |     with recv_stream, send_stream, collapse_excgroups():\n    |                                    ~~~~~~~~~~~~~~~~~~^^\n    |   File \"C:\\Python313\\Lib\\contextlib.py\", line 162, in __exit__\n    |     self.gen.throw(value)\n    |     ~~~~~~~~~~~~~~^^^^^^^\n    |   File \"C:\\service-gateway\\venv\\Lib\\site-packages\\starlette\\_utils.py\", line 85, in collapse_excgroups\n    |     raise exc\n    |   File \"C:\\service-gateway\\venv\\Lib\\site-packages\\starlette\\middleware\\base.py\", line 184, in __call__\n    |     response = await self.dispatch_func(request, call_next)\n    |                ^^^^^^^^^^^^^^^^^^^^^^^^^^^^^^^^^^^^^^^^^^^^\n    |   File \"C:\\service-gateway\\utils\\request_middleware.py\", line 15, in dispatch\n    |     response = await call_next(request)\n    |                ^^^^^^^^^^^^^^^^^^^^^^^^\n    |   File \"C:\\service-gateway\\venv\\Lib\\site-packages\\starlette\\middleware\\base.py\", line 159, in call_next\n    |     raise app_exc\n    |   File \"C:\\service-gateway\\venv\\Lib\\site-packages\\starlette\\middleware\\base.py\", line 144, in coro\n    |     await self.app(scope, receive_or_disconnect, send_no_error)\n    |   File \"C:\\service-gateway\\venv\\Lib\\site-packages\\starlette\\middleware\\exceptions.py\", line 63, in __call__\n    |     await wrap_app_handling_exceptions(self.app, conn)(scope, receive, send)\n    |   File \"C:\\service-gateway\\venv\\Lib\\site-packages\\starlette\\_exception_handler.py\", line 53, in wrapped_app\n    |     raise exc\n    |   File \"C:\\service-gateway\\venv\\Lib\\site-packages\\starlette\\_exception_handler.py\", line 42, in wrapped_app\n    |     await app(scope, receive, sender)\n    |   File \"C:\\service-gateway\\venv\\Lib\\site-packages\\starlette\\routing.py\", line 716, in __call__\n    |     await self.middleware_stack(scope, receive, send)\n    |   File \"C:\\service-gateway\\venv\\Lib\\site-packages\\starlette\\routing.py\", line 736, in app\n    |     await route.handle(scope, receive, send)\n    |   File \"C:\\service-gateway\\venv\\Lib\\site-packages\\starlette\\routing.py\", line 290, in handle\n    |     await self.app(scope, receive, send)\n    |   File \"C:\\service-gateway\\venv\\Lib\\site-packages\\starlette\\routing.py\", line 78, in app\n    |     await wrap_app_handling_exceptions(app, request)(scope, receive, send)\n    |   File \"C:\\service-gateway\\venv\\Lib\\site-packages\\starlette\\_exception_handler.py\", line 59, in wrapped_app\n    |     response = await handler(conn, exc)\n    |                ^^^^^^^^^^^^^^^^^^^^^^^^\n    |   File \"C:\\service-gateway\\utils\\error_handler.py\", line 100, in validation_exception_handler\n    |     status_code=exc.status_code,\n    |                 ^^^^^^^^^^^^^^^\n    | AttributeError: 'RequestValidationError' object has no attribute 'status_code'\n    +------------------------------------\n\nDuring handling of the above exception, another exception occurred:\n\nTraceback (most recent call last):\n  File \"C:\\service-gateway\\venv\\Lib\\site-packages\\starlette\\middleware\\errors.py\", line 164, in __call__\n    await self.app(scope, receive, _send)\n  File \"C:\\service-gateway\\venv\\Lib\\site-packages\\starlette\\middleware\\cors.py\", line 85, in __call__\n    await self.app(scope, receive, send)\n  File \"C:\\service-gateway\\venv\\Lib\\site-packages\\starlette\\middleware\\base.py\", line 182, in __call__\n    with recv_stream, send_stream, collapse_excgroups():\n                                   ~~~~~~~~~~~~~~~~~~^^\n  File \"C:\\Python313\\Lib\\contextlib.py\", line 162, in __exit__\n    self.gen.throw(value)\n    ~~~~~~~~~~~~~~^^^^^^^\n  File \"C:\\service-gateway\\venv\\Lib\\site-packages\\starlette\\_utils.py\", line 85, in collapse_excgroups\n    raise exc\n  File \"C:\\service-gateway\\venv\\Lib\\site-packages\\starlette\\middleware\\base.py\", line 184, in __call__\n    response = await self.dispatch_func(request, call_next)\n               ^^^^^^^^^^^^^^^^^^^^^^^^^^^^^^^^^^^^^^^^^^^^\n  File \"C:\\service-gateway\\utils\\request_middleware.py\", line 15, in dispatch\n    response = await call_next(request)\n               ^^^^^^^^^^^^^^^^^^^^^^^^\n  File \"C:\\service-gateway\\venv\\Lib\\site-packages\\starlette\\middleware\\base.py\", line 159, in call_next\n    raise app_exc\n  File \"C:\\service-gateway\\venv\\Lib\\site-packages\\starlette\\middleware\\base.py\", line 144, in coro\n    await self.app(scope, receive_or_disconnect, send_no_error)\n  File \"C:\\service-gateway\\venv\\Lib\\site-packages\\starlette\\middleware\\exceptions.py\", line 63, in __call__\n    await wrap_app_handling_exceptions(self.app, conn)(scope, receive, send)\n  File \"C:\\service-gateway\\venv\\Lib\\site-packages\\starlette\\_exception_handler.py\", line 53, in wrapped_app\n    raise exc\n  File \"C:\\service-gateway\\venv\\Lib\\site-packages\\starlette\\_exception_handler.py\", line 42, in wrapped_app\n    await app(scope, receive, sender)\n  File \"C:\\service-gateway\\venv\\Lib\\site-packages\\starlette\\routing.py\", line 716, in __call__\n    await self.middleware_stack(scope, receive, send)\n  File \"C:\\service-gateway\\venv\\Lib\\site-packages\\starlette\\routing.py\", line 736, in app\n    await route.handle(scope, receive, send)\n  File \"C:\\service-gateway\\venv\\Lib\\site-packages\\starlette\\routing.py\", line 290, in handle\n    await self.app(scope, receive, send)\n  File \"C:\\service-gateway\\venv\\Lib\\site-packages\\starlette\\routing.py\", line 78, in app\n    await wrap_app_handling_exceptions(app, request)(scope, receive, send)\n  File \"C:\\service-gateway\\venv\\Lib\\site-packages\\starlette\\_exception_handler.py\", line 59, in wrapped_app\n    response = await handler(conn, exc)\n               ^^^^^^^^^^^^^^^^^^^^^^^^\n  File \"C:\\service-gateway\\utils\\error_handler.py\", line 100, in validation_exception_handler\n    status_code=exc.status_code,\n                ^^^^^^^^^^^^^^^\nAttributeError: 'RequestValidationError' object has no attribute 'status_code'\n", "exception_type": "AttributeError"}}
2025-10-09 15:12:04 | ERROR | {"request_id": "ec6bfa78-4f99-4f45-a731-4f24337c033b", "timestamp": "2025-10-09T15:12:04.239510", "client_ip": "10.200.0.1", "endpoint": "/api/permission-requests/27/deny", "error_type": "RequestValidationError", "error_message": "[{'type': 'string_type', 'loc': ('body',), 'msg': 'Input should be a valid string', 'input': {'review_notes': 'o'}}]", "error_code": "VALIDATION_ERROR", "additional_context": {"validation_errors": [{"field": "", "message": "Input should be a valid string", "type": "string_type"}]}}
2025-10-09 15:12:04 | ERROR | {"request_id": "ec6bfa78-4f99-4f45-a731-4f24337c033b", "timestamp": "2025-10-09T15:12:04.245655", "client_ip": "10.200.0.1", "endpoint": "/api/permission-requests/27/deny", "error_type": "AttributeError", "error_message": "'RequestValidationError' object has no attribute 'status_code'", "error_code": "INTERNAL_ERROR", "additional_context": {"traceback": "  + Exception Group Traceback (most recent call last):\n  |   File \"C:\\service-gateway\\venv\\Lib\\site-packages\\starlette\\_utils.py\", line 79, in collapse_excgroups\n  |     yield\n  |   File \"C:\\service-gateway\\venv\\Lib\\site-packages\\starlette\\middleware\\base.py\", line 183, in __call__\n  |     async with anyio.create_task_group() as task_group:\n  |                ~~~~~~~~~~~~~~~~~~~~~~~^^\n  |   File \"C:\\service-gateway\\venv\\Lib\\site-packages\\anyio\\_backends\\_asyncio.py\", line 781, in __aexit__\n  |     raise BaseExceptionGroup(\n  |         \"unhandled errors in a TaskGroup\", self._exceptions\n  |     ) from None\n  | ExceptionGroup: unhandled errors in a TaskGroup (1 sub-exception)\n  +-+---------------- 1 ----------------\n    | Traceback (most recent call last):\n    |   File \"C:\\service-gateway\\venv\\Lib\\site-packages\\starlette\\middleware\\errors.py\", line 164, in __call__\n    |     await self.app(scope, receive, _send)\n    |   File \"C:\\service-gateway\\venv\\Lib\\site-packages\\starlette\\middleware\\cors.py\", line 85, in __call__\n    |     await self.app(scope, receive, send)\n    |   File \"C:\\service-gateway\\venv\\Lib\\site-packages\\starlette\\middleware\\base.py\", line 182, in __call__\n    |     with recv_stream, send_stream, collapse_excgroups():\n    |                                    ~~~~~~~~~~~~~~~~~~^^\n    |   File \"C:\\Python313\\Lib\\contextlib.py\", line 162, in __exit__\n    |     self.gen.throw(value)\n    |     ~~~~~~~~~~~~~~^^^^^^^\n    |   File \"C:\\service-gateway\\venv\\Lib\\site-packages\\starlette\\_utils.py\", line 85, in collapse_excgroups\n    |     raise exc\n    |   File \"C:\\service-gateway\\venv\\Lib\\site-packages\\starlette\\middleware\\base.py\", line 184, in __call__\n    |     response = await self.dispatch_func(request, call_next)\n    |                ^^^^^^^^^^^^^^^^^^^^^^^^^^^^^^^^^^^^^^^^^^^^\n    |   File \"C:\\service-gateway\\utils\\request_middleware.py\", line 15, in dispatch\n    |     response = await call_next(request)\n    |                ^^^^^^^^^^^^^^^^^^^^^^^^\n    |   File \"C:\\service-gateway\\venv\\Lib\\site-packages\\starlette\\middleware\\base.py\", line 159, in call_next\n    |     raise app_exc\n    |   File \"C:\\service-gateway\\venv\\Lib\\site-packages\\starlette\\middleware\\base.py\", line 144, in coro\n    |     await self.app(scope, receive_or_disconnect, send_no_error)\n    |   File \"C:\\service-gateway\\venv\\Lib\\site-packages\\starlette\\middleware\\exceptions.py\", line 63, in __call__\n    |     await wrap_app_handling_exceptions(self.app, conn)(scope, receive, send)\n    |   File \"C:\\service-gateway\\venv\\Lib\\site-packages\\starlette\\_exception_handler.py\", line 53, in wrapped_app\n    |     raise exc\n    |   File \"C:\\service-gateway\\venv\\Lib\\site-packages\\starlette\\_exception_handler.py\", line 42, in wrapped_app\n    |     await app(scope, receive, sender)\n    |   File \"C:\\service-gateway\\venv\\Lib\\site-packages\\starlette\\routing.py\", line 716, in __call__\n    |     await self.middleware_stack(scope, receive, send)\n    |   File \"C:\\service-gateway\\venv\\Lib\\site-packages\\starlette\\routing.py\", line 736, in app\n    |     await route.handle(scope, receive, send)\n    |   File \"C:\\service-gateway\\venv\\Lib\\site-packages\\starlette\\routing.py\", line 290, in handle\n    |     await self.app(scope, receive, send)\n    |   File \"C:\\service-gateway\\venv\\Lib\\site-packages\\starlette\\routing.py\", line 78, in app\n    |     await wrap_app_handling_exceptions(app, request)(scope, receive, send)\n    |   File \"C:\\service-gateway\\venv\\Lib\\site-packages\\starlette\\_exception_handler.py\", line 59, in wrapped_app\n    |     response = await handler(conn, exc)\n    |                ^^^^^^^^^^^^^^^^^^^^^^^^\n    |   File \"C:\\service-gateway\\utils\\error_handler.py\", line 100, in validation_exception_handler\n    |     status_code=exc.status_code,\n    |                 ^^^^^^^^^^^^^^^\n    | AttributeError: 'RequestValidationError' object has no attribute 'status_code'\n    +------------------------------------\n\nDuring handling of the above exception, another exception occurred:\n\nTraceback (most recent call last):\n  File \"C:\\service-gateway\\venv\\Lib\\site-packages\\starlette\\middleware\\errors.py\", line 164, in __call__\n    await self.app(scope, receive, _send)\n  File \"C:\\service-gateway\\venv\\Lib\\site-packages\\starlette\\middleware\\cors.py\", line 85, in __call__\n    await self.app(scope, receive, send)\n  File \"C:\\service-gateway\\venv\\Lib\\site-packages\\starlette\\middleware\\base.py\", line 182, in __call__\n    with recv_stream, send_stream, collapse_excgroups():\n                                   ~~~~~~~~~~~~~~~~~~^^\n  File \"C:\\Python313\\Lib\\contextlib.py\", line 162, in __exit__\n    self.gen.throw(value)\n    ~~~~~~~~~~~~~~^^^^^^^\n  File \"C:\\service-gateway\\venv\\Lib\\site-packages\\starlette\\_utils.py\", line 85, in collapse_excgroups\n    raise exc\n  File \"C:\\service-gateway\\venv\\Lib\\site-packages\\starlette\\middleware\\base.py\", line 184, in __call__\n    response = await self.dispatch_func(request, call_next)\n               ^^^^^^^^^^^^^^^^^^^^^^^^^^^^^^^^^^^^^^^^^^^^\n  File \"C:\\service-gateway\\utils\\request_middleware.py\", line 15, in dispatch\n    response = await call_next(request)\n               ^^^^^^^^^^^^^^^^^^^^^^^^\n  File \"C:\\service-gateway\\venv\\Lib\\site-packages\\starlette\\middleware\\base.py\", line 159, in call_next\n    raise app_exc\n  File \"C:\\service-gateway\\venv\\Lib\\site-packages\\starlette\\middleware\\base.py\", line 144, in coro\n    await self.app(scope, receive_or_disconnect, send_no_error)\n  File \"C:\\service-gateway\\venv\\Lib\\site-packages\\starlette\\middleware\\exceptions.py\", line 63, in __call__\n    await wrap_app_handling_exceptions(self.app, conn)(scope, receive, send)\n  File \"C:\\service-gateway\\venv\\Lib\\site-packages\\starlette\\_exception_handler.py\", line 53, in wrapped_app\n    raise exc\n  File \"C:\\service-gateway\\venv\\Lib\\site-packages\\starlette\\_exception_handler.py\", line 42, in wrapped_app\n    await app(scope, receive, sender)\n  File \"C:\\service-gateway\\venv\\Lib\\site-packages\\starlette\\routing.py\", line 716, in __call__\n    await self.middleware_stack(scope, receive, send)\n  File \"C:\\service-gateway\\venv\\Lib\\site-packages\\starlette\\routing.py\", line 736, in app\n    await route.handle(scope, receive, send)\n  File \"C:\\service-gateway\\venv\\Lib\\site-packages\\starlette\\routing.py\", line 290, in handle\n    await self.app(scope, receive, send)\n  File \"C:\\service-gateway\\venv\\Lib\\site-packages\\starlette\\routing.py\", line 78, in app\n    await wrap_app_handling_exceptions(app, request)(scope, receive, send)\n  File \"C:\\service-gateway\\venv\\Lib\\site-packages\\starlette\\_exception_handler.py\", line 59, in wrapped_app\n    response = await handler(conn, exc)\n               ^^^^^^^^^^^^^^^^^^^^^^^^\n  File \"C:\\service-gateway\\utils\\error_handler.py\", line 100, in validation_exception_handler\n    status_code=exc.status_code,\n                ^^^^^^^^^^^^^^^\nAttributeError: 'RequestValidationError' object has no attribute 'status_code'\n", "exception_type": "AttributeError"}}
2025-10-09 15:12:09 | ERROR | {"request_id": "99ba5f47-c075-424a-a0e6-1d208875dcc9", "timestamp": "2025-10-09T15:12:09.852525", "client_ip": "10.200.0.1", "endpoint": "/api/permission-requests/28/deny", "error_type": "RequestValidationError", "error_message": "[{'type': 'string_type', 'loc': ('body',), 'msg': 'Input should be a valid string', 'input': {'review_notes': 'o'}}]", "error_code": "VALIDATION_ERROR", "additional_context": {"validation_errors": [{"field": "", "message": "Input should be a valid string", "type": "string_type"}]}}
2025-10-09 15:12:09 | ERROR | {"request_id": "99ba5f47-c075-424a-a0e6-1d208875dcc9", "timestamp": "2025-10-09T15:12:09.858546", "client_ip": "10.200.0.1", "endpoint": "/api/permission-requests/28/deny", "error_type": "AttributeError", "error_message": "'RequestValidationError' object has no attribute 'status_code'", "error_code": "INTERNAL_ERROR", "additional_context": {"traceback": "  + Exception Group Traceback (most recent call last):\n  |   File \"C:\\service-gateway\\venv\\Lib\\site-packages\\starlette\\_utils.py\", line 79, in collapse_excgroups\n  |     yield\n  |   File \"C:\\service-gateway\\venv\\Lib\\site-packages\\starlette\\middleware\\base.py\", line 183, in __call__\n  |     async with anyio.create_task_group() as task_group:\n  |                ~~~~~~~~~~~~~~~~~~~~~~~^^\n  |   File \"C:\\service-gateway\\venv\\Lib\\site-packages\\anyio\\_backends\\_asyncio.py\", line 781, in __aexit__\n  |     raise BaseExceptionGroup(\n  |         \"unhandled errors in a TaskGroup\", self._exceptions\n  |     ) from None\n  | ExceptionGroup: unhandled errors in a TaskGroup (1 sub-exception)\n  +-+---------------- 1 ----------------\n    | Traceback (most recent call last):\n    |   File \"C:\\service-gateway\\venv\\Lib\\site-packages\\starlette\\middleware\\errors.py\", line 164, in __call__\n    |     await self.app(scope, receive, _send)\n    |   File \"C:\\service-gateway\\venv\\Lib\\site-packages\\starlette\\middleware\\cors.py\", line 85, in __call__\n    |     await self.app(scope, receive, send)\n    |   File \"C:\\service-gateway\\venv\\Lib\\site-packages\\starlette\\middleware\\base.py\", line 182, in __call__\n    |     with recv_stream, send_stream, collapse_excgroups():\n    |                                    ~~~~~~~~~~~~~~~~~~^^\n    |   File \"C:\\Python313\\Lib\\contextlib.py\", line 162, in __exit__\n    |     self.gen.throw(value)\n    |     ~~~~~~~~~~~~~~^^^^^^^\n    |   File \"C:\\service-gateway\\venv\\Lib\\site-packages\\starlette\\_utils.py\", line 85, in collapse_excgroups\n    |     raise exc\n    |   File \"C:\\service-gateway\\venv\\Lib\\site-packages\\starlette\\middleware\\base.py\", line 184, in __call__\n    |     response = await self.dispatch_func(request, call_next)\n    |                ^^^^^^^^^^^^^^^^^^^^^^^^^^^^^^^^^^^^^^^^^^^^\n    |   File \"C:\\service-gateway\\utils\\request_middleware.py\", line 15, in dispatch\n    |     response = await call_next(request)\n    |                ^^^^^^^^^^^^^^^^^^^^^^^^\n    |   File \"C:\\service-gateway\\venv\\Lib\\site-packages\\starlette\\middleware\\base.py\", line 159, in call_next\n    |     raise app_exc\n    |   File \"C:\\service-gateway\\venv\\Lib\\site-packages\\starlette\\middleware\\base.py\", line 144, in coro\n    |     await self.app(scope, receive_or_disconnect, send_no_error)\n    |   File \"C:\\service-gateway\\venv\\Lib\\site-packages\\starlette\\middleware\\exceptions.py\", line 63, in __call__\n    |     await wrap_app_handling_exceptions(self.app, conn)(scope, receive, send)\n    |   File \"C:\\service-gateway\\venv\\Lib\\site-packages\\starlette\\_exception_handler.py\", line 53, in wrapped_app\n    |     raise exc\n    |   File \"C:\\service-gateway\\venv\\Lib\\site-packages\\starlette\\_exception_handler.py\", line 42, in wrapped_app\n    |     await app(scope, receive, sender)\n    |   File \"C:\\service-gateway\\venv\\Lib\\site-packages\\starlette\\routing.py\", line 716, in __call__\n    |     await self.middleware_stack(scope, receive, send)\n    |   File \"C:\\service-gateway\\venv\\Lib\\site-packages\\starlette\\routing.py\", line 736, in app\n    |     await route.handle(scope, receive, send)\n    |   File \"C:\\service-gateway\\venv\\Lib\\site-packages\\starlette\\routing.py\", line 290, in handle\n    |     await self.app(scope, receive, send)\n    |   File \"C:\\service-gateway\\venv\\Lib\\site-packages\\starlette\\routing.py\", line 78, in app\n    |     await wrap_app_handling_exceptions(app, request)(scope, receive, send)\n    |   File \"C:\\service-gateway\\venv\\Lib\\site-packages\\starlette\\_exception_handler.py\", line 59, in wrapped_app\n    |     response = await handler(conn, exc)\n    |                ^^^^^^^^^^^^^^^^^^^^^^^^\n    |   File \"C:\\service-gateway\\utils\\error_handler.py\", line 100, in validation_exception_handler\n    |     status_code=exc.status_code,\n    |                 ^^^^^^^^^^^^^^^\n    | AttributeError: 'RequestValidationError' object has no attribute 'status_code'\n    +------------------------------------\n\nDuring handling of the above exception, another exception occurred:\n\nTraceback (most recent call last):\n  File \"C:\\service-gateway\\venv\\Lib\\site-packages\\starlette\\middleware\\errors.py\", line 164, in __call__\n    await self.app(scope, receive, _send)\n  File \"C:\\service-gateway\\venv\\Lib\\site-packages\\starlette\\middleware\\cors.py\", line 85, in __call__\n    await self.app(scope, receive, send)\n  File \"C:\\service-gateway\\venv\\Lib\\site-packages\\starlette\\middleware\\base.py\", line 182, in __call__\n    with recv_stream, send_stream, collapse_excgroups():\n                                   ~~~~~~~~~~~~~~~~~~^^\n  File \"C:\\Python313\\Lib\\contextlib.py\", line 162, in __exit__\n    self.gen.throw(value)\n    ~~~~~~~~~~~~~~^^^^^^^\n  File \"C:\\service-gateway\\venv\\Lib\\site-packages\\starlette\\_utils.py\", line 85, in collapse_excgroups\n    raise exc\n  File \"C:\\service-gateway\\venv\\Lib\\site-packages\\starlette\\middleware\\base.py\", line 184, in __call__\n    response = await self.dispatch_func(request, call_next)\n               ^^^^^^^^^^^^^^^^^^^^^^^^^^^^^^^^^^^^^^^^^^^^\n  File \"C:\\service-gateway\\utils\\request_middleware.py\", line 15, in dispatch\n    response = await call_next(request)\n               ^^^^^^^^^^^^^^^^^^^^^^^^\n  File \"C:\\service-gateway\\venv\\Lib\\site-packages\\starlette\\middleware\\base.py\", line 159, in call_next\n    raise app_exc\n  File \"C:\\service-gateway\\venv\\Lib\\site-packages\\starlette\\middleware\\base.py\", line 144, in coro\n    await self.app(scope, receive_or_disconnect, send_no_error)\n  File \"C:\\service-gateway\\venv\\Lib\\site-packages\\starlette\\middleware\\exceptions.py\", line 63, in __call__\n    await wrap_app_handling_exceptions(self.app, conn)(scope, receive, send)\n  File \"C:\\service-gateway\\venv\\Lib\\site-packages\\starlette\\_exception_handler.py\", line 53, in wrapped_app\n    raise exc\n  File \"C:\\service-gateway\\venv\\Lib\\site-packages\\starlette\\_exception_handler.py\", line 42, in wrapped_app\n    await app(scope, receive, sender)\n  File \"C:\\service-gateway\\venv\\Lib\\site-packages\\starlette\\routing.py\", line 716, in __call__\n    await self.middleware_stack(scope, receive, send)\n  File \"C:\\service-gateway\\venv\\Lib\\site-packages\\starlette\\routing.py\", line 736, in app\n    await route.handle(scope, receive, send)\n  File \"C:\\service-gateway\\venv\\Lib\\site-packages\\starlette\\routing.py\", line 290, in handle\n    await self.app(scope, receive, send)\n  File \"C:\\service-gateway\\venv\\Lib\\site-packages\\starlette\\routing.py\", line 78, in app\n    await wrap_app_handling_exceptions(app, request)(scope, receive, send)\n  File \"C:\\service-gateway\\venv\\Lib\\site-packages\\starlette\\_exception_handler.py\", line 59, in wrapped_app\n    response = await handler(conn, exc)\n               ^^^^^^^^^^^^^^^^^^^^^^^^\n  File \"C:\\service-gateway\\utils\\error_handler.py\", line 100, in validation_exception_handler\n    status_code=exc.status_code,\n                ^^^^^^^^^^^^^^^\nAttributeError: 'RequestValidationError' object has no attribute 'status_code'\n", "exception_type": "AttributeError"}}
2025-10-09 15:13:59 | ERROR | {"request_id": "8270fd08-6ca3-4e64-aed2-2c645f3a9338", "timestamp": "2025-10-09T15:13:59.265168", "client_ip": "10.200.0.1", "endpoint": "/api/execute-query", "error_type": "HTTPException", "error_message": "403: Column KHKG\u00c4 is restricted. Permission request #53 created.", "error_code": "HTTP_403", "additional_context": {"original_detail": "Column KHKG\u00c4 is restricted. Permission request #53 created."}}
2025-10-09 15:14:19 | ERROR | {"request_id": "2d7f4b72-c8a9-4303-93c9-8d4400219860", "timestamp": "2025-10-09T15:14:19.383816", "client_ip": "10.200.0.1", "endpoint": "/api/execute-query", "error_type": "HTTPException", "error_message": "403: Column KHKG\u00c4 is restricted. Permission request #55 created.", "error_code": "HTTP_403", "additional_context": {"original_detail": "Column KHKG\u00c4 is restricted. Permission request #55 created."}}
2025-10-09 15:43:22 | ERROR | {"request_id": "521a463d-60ca-4038-884b-9490575e4629", "timestamp": "2025-10-09T15:43:22.453561", "client_ip": "10.200.0.1", "endpoint": "/api/execute-query", "error_type": "HTTPException", "error_message": "403: Column KHKG\u00c4 is restricted. Permission request #56 created.", "error_code": "HTTP_403", "additional_context": {"original_detail": "Column KHKG\u00c4 is restricted. Permission request #56 created."}}
2025-10-09 16:39:03 | ERROR | {"request_id": "720b27e6-1955-4c6f-9f4f-eac8d3e779e9", "timestamp": "2025-10-09T16:39:03.797971", "client_ip": "10.200.0.1", "endpoint": "/api/execute-query", "error_type": "HTTPException", "error_message": "403: Column KHKG\u00c4 is restricted. Permission request #57 created.", "error_code": "HTTP_403", "additional_context": {"original_detail": "Column KHKG\u00c4 is restricted. Permission request #57 created."}}
2025-10-10 11:02:54 | ERROR | {"request_id": "b7c3f299-cd50-4a6a-b0a1-8fefb3721d96", "timestamp": "2025-10-10T11:02:54.371782", "client_ip": "10.200.0.1", "endpoint": "/api/execute-query", "error_type": "HTTPException", "error_message": "403: Column KHKG\u00c4 is restricted. Permission request #58 created.", "error_code": "HTTP_403", "additional_context": {"original_detail": "Column KHKG\u00c4 is restricted. Permission request #58 created."}}
2025-10-10 15:54:04 | ERROR | {"request_id": "8ac38b9e-6fa8-4c53-aa7b-0c7bc4603899", "timestamp": "2025-10-10T15:54:04.162054", "client_ip": "10.200.0.1", "endpoint": "/api/styr/execute-query", "error_type": "HTTPException", "error_message": "500: ('IM014', '[IM014] [Microsoft][ODBC Driver Manager] The specified DSN contains an architecture mismatch between the Driver and Application (0) (SQLDriverConnect)')", "error_code": "HTTP_500", "additional_context": {"original_detail": "('IM014', '[IM014] [Microsoft][ODBC Driver Manager] The specified DSN contains an architecture mismatch between the Driver and Application (0) (SQLDriverConnect)')"}}
2025-10-10 16:02:41 | ERROR | {"request_id": "4832517b-1790-47c7-a766-c525eb0ae455", "timestamp": "2025-10-10T16:02:41.845722", "client_ip": "10.200.0.1", "endpoint": "/api/styr/execute-query", "error_type": "HTTPException", "error_message": "500: ('IM014', '[IM014] [Microsoft][ODBC Driver Manager] The specified DSN contains an architecture mismatch between the Driver and Application (0) (SQLDriverConnect)')", "error_code": "HTTP_500", "additional_context": {"original_detail": "('IM014', '[IM014] [Microsoft][ODBC Driver Manager] The specified DSN contains an architecture mismatch between the Driver and Application (0) (SQLDriverConnect)')"}}
2025-10-10 16:04:09 | ERROR | {"request_id": "3cf44357-8dc4-4bdf-81dd-3f86cef81062", "timestamp": "2025-10-10T16:04:09.276184", "client_ip": "10.200.0.1", "endpoint": "/api/styr/execute-query", "error_type": "HTTPException", "error_message": "500: ('IM014', '[IM014] [Microsoft][ODBC Driver Manager] The specified DSN contains an architecture mismatch between the Driver and Application (0) (SQLDriverConnect)')", "error_code": "HTTP_500", "additional_context": {"original_detail": "('IM014', '[IM014] [Microsoft][ODBC Driver Manager] The specified DSN contains an architecture mismatch between the Driver and Application (0) (SQLDriverConnect)')"}}
2025-10-10 16:06:05 | ERROR | {"request_id": "e24e62f4-af30-4fc2-8122-a510a9b4885d", "timestamp": "2025-10-10T16:06:05.029041", "client_ip": "10.200.0.1", "endpoint": "/api/styr/execute-query", "error_type": "HTTPException", "error_message": "500: ('IM014', '[IM014] [Microsoft][ODBC Driver Manager] The specified DSN contains an architecture mismatch between the Driver and Application (0) (SQLDriverConnect)')", "error_code": "HTTP_500", "additional_context": {"original_detail": "('IM014', '[IM014] [Microsoft][ODBC Driver Manager] The specified DSN contains an architecture mismatch between the Driver and Application (0) (SQLDriverConnect)')"}}
2025-10-10 16:14:09 | ERROR | {"request_id": "06ce2b5e-89ab-4ab4-9b47-e99e5ba87efd", "timestamp": "2025-10-10T16:14:09.507672", "client_ip": "10.200.0.1", "endpoint": "/api/styr/execute-query", "error_type": "HTTPException", "error_message": "500: ('IM014', '[IM014] [Microsoft][ODBC Driver Manager] The specified DSN contains an architecture mismatch between the Driver and Application (0) (SQLDriverConnect)')", "error_code": "HTTP_500", "additional_context": {"original_detail": "('IM014', '[IM014] [Microsoft][ODBC Driver Manager] The specified DSN contains an architecture mismatch between the Driver and Application (0) (SQLDriverConnect)')"}}
2025-10-10 16:14:33 | ERROR | {"request_id": "cdce54cb-0295-4e8a-9b93-cf47830ea96c", "timestamp": "2025-10-10T16:14:33.960841", "client_ip": "10.200.0.1", "endpoint": "/api/styr/execute-query", "error_type": "HTTPException", "error_message": "500: ('IM014', '[IM014] [Microsoft][ODBC Driver Manager] The specified DSN contains an architecture mismatch between the Driver and Application (0) (SQLDriverConnect)')", "error_code": "HTTP_500", "additional_context": {"original_detail": "('IM014', '[IM014] [Microsoft][ODBC Driver Manager] The specified DSN contains an architecture mismatch between the Driver and Application (0) (SQLDriverConnect)')"}}
2025-10-10 16:15:23 | ERROR | {"request_id": "eb7397dc-2bca-4399-9cd3-09af86122635", "timestamp": "2025-10-10T16:15:23.218901", "client_ip": "10.200.0.1", "endpoint": "/api/styr/execute-query", "error_type": "HTTPException", "error_message": "500: ('IM014', '[IM014] [Microsoft][ODBC Driver Manager] The specified DSN contains an architecture mismatch between the Driver and Application (0) (SQLDriverConnect)')", "error_code": "HTTP_500", "additional_context": {"original_detail": "('IM014', '[IM014] [Microsoft][ODBC Driver Manager] The specified DSN contains an architecture mismatch between the Driver and Application (0) (SQLDriverConnect)')"}}
2025-10-10 16:15:55 | ERROR | {"request_id": "4e61e798-78b7-4eba-81f4-8ddf390ef1c5", "timestamp": "2025-10-10T16:15:55.930534", "client_ip": "10.200.0.1", "endpoint": "/api/styr/execute-query", "error_type": "HTTPException", "error_message": "500: ('IM014', '[IM014] [Microsoft][ODBC Driver Manager] The specified DSN contains an architecture mismatch between the Driver and Application (0) (SQLDriverConnect)')", "error_code": "HTTP_500", "additional_context": {"original_detail": "('IM014', '[IM014] [Microsoft][ODBC Driver Manager] The specified DSN contains an architecture mismatch between the Driver and Application (0) (SQLDriverConnect)')"}}
2025-10-13 14:12:36 | ERROR | {"request_id": "e84c5d7c-7833-4dc2-8a4a-07f8bcc272ac", "timestamp": "2025-10-13T14:12:36.332860", "client_ip": "10.200.0.1", "endpoint": "/api/execute-query", "error_type": "HTTPException", "error_message": "401: Invalid user", "error_code": "HTTP_401", "additional_context": {"original_detail": "Invalid user"}}
2025-10-14 09:54:17 | ERROR | {"request_id": "597e5dd0-d246-49ed-9b62-dcae37e3c00d", "timestamp": "2025-10-14T09:54:17.071018", "client_ip": "10.200.0.1", "endpoint": "/api/execute-query", "error_type": "HTTPException", "error_message": "401: Invalid user", "error_code": "HTTP_401", "additional_context": {"original_detail": "Invalid user"}}
2025-10-14 10:35:23 | ERROR | {"request_id": "bbd136de-071e-4d65-bcad-76b8f82075d2", "timestamp": "2025-10-14T10:35:23.918763", "client_ip": "10.200.0.1", "endpoint": "/api/execute-query", "error_type": "HTTPException", "error_message": "401: Invalid user", "error_code": "HTTP_401", "additional_context": {"original_detail": "Invalid user"}}
2025-10-14 10:48:49 | ERROR | {"request_id": "49c6e020-77f8-4204-9f71-2f8bb118d27a", "timestamp": "2025-10-14T10:48:49.467700", "client_ip": "10.200.0.1", "endpoint": "/api/execute-query", "error_type": "HTTPException", "error_message": "401: Invalid user", "error_code": "HTTP_401", "additional_context": {"original_detail": "Invalid user"}}
2025-10-14 10:53:49 | ERROR | {"request_id": "ee30a42d-e845-4316-bb3d-fe183b9145e1", "timestamp": "2025-10-14T10:53:49.114127", "client_ip": "10.200.0.1", "endpoint": "/api/execute-query", "error_type": "HTTPException", "error_message": "401: Invalid user", "error_code": "HTTP_401", "additional_context": {"original_detail": "Invalid user"}}
2025-10-14 10:59:59 | ERROR | {"request_id": "9f37c90c-3b35-4f9f-972f-d65986d09759", "timestamp": "2025-10-14T10:59:59.624491", "client_ip": "10.200.0.1", "endpoint": "/api/execute-query", "error_type": "HTTPException", "error_message": "401: Invalid user", "error_code": "HTTP_401", "additional_context": {"original_detail": "Invalid user"}}
2025-10-14 11:02:02 | ERROR | {"request_id": "0b70e5b3-afc4-4c74-b359-1ccbb07949c1", "timestamp": "2025-10-14T11:02:02.523618", "client_ip": "10.200.0.1", "endpoint": "/api/execute-query", "error_type": "HTTPException", "error_message": "401: Invalid user", "error_code": "HTTP_401", "additional_context": {"original_detail": "Invalid user"}}
2025-10-14 11:06:57 | ERROR | {"request_id": "473adfaa-3c42-469a-89cc-678379178431", "timestamp": "2025-10-14T11:06:57.481569", "client_ip": "10.200.0.1", "endpoint": "/api/execute-query", "error_type": "HTTPException", "error_message": "401: Invalid user", "error_code": "HTTP_401", "additional_context": {"original_detail": "Invalid user"}}
2025-10-14 11:46:00 | ERROR | {"request_id": "ab9a7b02-230e-40be-a002-c4640fd34e30", "timestamp": "2025-10-14T11:46:00.918693", "client_ip": "10.200.0.1", "endpoint": "/api/execute-query", "error_type": "HTTPException", "error_message": "401: Invalid user", "error_code": "HTTP_401", "additional_context": {"original_detail": "Invalid user"}}
2025-10-14 11:48:05 | ERROR | {"request_id": "0eb95dbd-ae34-4a18-a897-7df03edb9878", "timestamp": "2025-10-14T11:48:05.394530", "client_ip": "10.200.0.1", "endpoint": "/api/execute-query", "error_type": "HTTPException", "error_message": "401: Invalid user", "error_code": "HTTP_401", "additional_context": {"original_detail": "Invalid user"}}
2025-10-14 11:57:38 | ERROR | {"request_id": "fe0fd572-c095-4871-87e2-8504688497c0", "timestamp": "2025-10-14T11:57:38.250211", "client_ip": "10.200.0.1", "endpoint": "/api/execute-query-fsiah", "error_type": "HTTPException", "error_message": "500: ('28000', '[28000] [Microsoft][ODBC Driver 17 for SQL Server][SQL Server]Login failed for user \\'FSYS\\\\amila.g\\'. (18456) (SQLDriverConnect); [28000] [Microsoft][ODBC Driver 17 for SQL Server][SQL Server]Cannot open database \"YOUR_DATABASE_NAME\" requested by the login. The login failed. (4060); [28000] [Microsoft][ODBC Driver 17 for SQL Server][SQL Server]Login failed for user \\'FSYS\\\\amila.g\\'. (18456); [28000] [Microsoft][ODBC Driver 17 for SQL Server][SQL Server]Cannot open database \"YOUR_DATABASE_NAME\" requested by the login. The login failed. (4060)')", "error_code": "HTTP_500", "additional_context": {"original_detail": "('28000', '[28000] [Microsoft][ODBC Driver 17 for SQL Server][SQL Server]Login failed for user \\'FSYS\\\\amila.g\\'. (18456) (SQLDriverConnect); [28000] [Microsoft][ODBC Driver 17 for SQL Server][SQL Server]Cannot open database \"YOUR_DATABASE_NAME\" requested by the login. The login failed. (4060); [28000] [Microsoft][ODBC Driver 17 for SQL Server][SQL Server]Login failed for user \\'FSYS\\\\amila.g\\'. (18456); [28000] [Microsoft][ODBC Driver 17 for SQL Server][SQL Server]Cannot open database \"YOUR_DATABASE_NAME\" requested by the login. The login failed. (4060)')"}}
2025-10-14 13:01:43 | ERROR | {"request_id": "606e87f6-f7e7-4b82-9050-9f01bbffe326", "timestamp": "2025-10-14T13:01:43.618896", "client_ip": "10.200.0.1", "endpoint": "/api/execute-query-fsiah", "error_type": "HTTPException", "error_message": "500: ('42000', \"[42000] [Microsoft][ODBC Driver 17 for SQL Server][SQL Server]Incorrect syntax near ','. (102) (SQLExecDirectW)\")", "error_code": "HTTP_500", "additional_context": {"original_detail": "('42000', \"[42000] [Microsoft][ODBC Driver 17 for SQL Server][SQL Server]Incorrect syntax near ','. (102) (SQLExecDirectW)\")"}}
2025-10-14 15:35:15 | ERROR | {"request_id": "0ea6da27-ad43-4d06-b9df-a2e77c918fc5", "timestamp": "2025-10-14T15:35:15.999680", "client_ip": "10.200.0.1", "endpoint": "/api/styr/schema", "error_type": "HTTPException", "error_message": "500: ('IM014', '[IM014] [Microsoft][ODBC Driver Manager] The specified DSN contains an architecture mismatch between the Driver and Application (0) (SQLDriverConnect)')", "error_code": "HTTP_500", "additional_context": {"original_detail": "('IM014', '[IM014] [Microsoft][ODBC Driver Manager] The specified DSN contains an architecture mismatch between the Driver and Application (0) (SQLDriverConnect)')"}}
2025-10-14 15:35:43 | ERROR | {"request_id": "1962af13-9555-4612-b5b2-6ccabdd0b415", "timestamp": "2025-10-14T15:35:43.214768", "client_ip": "10.200.0.1", "endpoint": "/api/styr/schema", "error_type": "HTTPException", "error_message": "500: ('IM014', '[IM014] [Microsoft][ODBC Driver Manager] The specified DSN contains an architecture mismatch between the Driver and Application (0) (SQLDriverConnect)')", "error_code": "HTTP_500", "additional_context": {"original_detail": "('IM014', '[IM014] [Microsoft][ODBC Driver Manager] The specified DSN contains an architecture mismatch between the Driver and Application (0) (SQLDriverConnect)')"}}
2025-10-14 15:40:09 | ERROR | {"request_id": "9b786aa5-35b1-4f0c-b8b4-064ff558a436", "timestamp": "2025-10-14T15:40:09.231079", "client_ip": "10.200.0.1", "endpoint": "/api/styr/schema", "error_type": "HTTPException", "error_message": "500: ('IM014', '[IM014] [Microsoft][ODBC Driver Manager] The specified DSN contains an architecture mismatch between the Driver and Application (0) (SQLDriverConnect)')", "error_code": "HTTP_500", "additional_context": {"original_detail": "('IM014', '[IM014] [Microsoft][ODBC Driver Manager] The specified DSN contains an architecture mismatch between the Driver and Application (0) (SQLDriverConnect)')"}}
2025-10-14 15:41:09 | ERROR | {"request_id": "7fd2228f-f864-4b3b-bde7-74809cc5e189", "timestamp": "2025-10-14T15:41:09.621489", "client_ip": "10.200.0.1", "endpoint": "/api/STYR/schema", "error_type": "HTTPException", "error_message": "500: ('IM014', '[IM014] [Microsoft][ODBC Driver Manager] The specified DSN contains an architecture mismatch between the Driver and Application (0) (SQLDriverConnect)')", "error_code": "HTTP_500", "additional_context": {"original_detail": "('IM014', '[IM014] [Microsoft][ODBC Driver Manager] The specified DSN contains an architecture mismatch between the Driver and Application (0) (SQLDriverConnect)')"}}
2025-10-15 08:30:16 | ERROR | {"request_id": "aa14e8e2-ce33-4188-9c11-d2d2d6789179", "timestamp": "2025-10-15T08:30:16.827118", "client_ip": "10.200.0.1", "endpoint": "/api/STYR/schema-configured", "error_type": "HTTPException", "error_message": "404: Not Found", "error_code": "HTTP_404", "additional_context": {"original_detail": "Not Found"}}
2025-10-15 08:30:23 | ERROR | {"request_id": "0a54f974-7c9b-468b-b132-4dd93ce1f9df", "timestamp": "2025-10-15T08:30:23.856509", "client_ip": "10.200.0.1", "endpoint": "/api/metadata/STYR/DCPO.KHKNDHUR", "error_type": "HTTPException", "error_message": "404: Not Found", "error_code": "HTTP_404", "additional_context": {"original_detail": "Not Found"}}
2025-10-15 08:30:38 | ERROR | {"request_id": "6e70ee54-3626-49ff-a67c-936e25debefb", "timestamp": "2025-10-15T08:30:38.086014", "client_ip": "10.200.0.1", "endpoint": "/api/metadata/save-extended", "error_type": "HTTPException", "error_message": "404: Not Found", "error_code": "HTTP_404", "additional_context": {"original_detail": "Not Found"}}
2025-10-15 08:30:46 | ERROR | {"request_id": "ef377ab3-efad-4c1f-9a3b-6b4927b90353", "timestamp": "2025-10-15T08:30:46.286076", "client_ip": "10.200.0.1", "endpoint": "/api/metadata/invalidate-cache", "error_type": "HTTPException", "error_message": "404: Not Found", "error_code": "HTTP_404", "additional_context": {"original_detail": "Not Found"}}
2025-10-15 08:37:52 | ERROR | {"request_id": "8033a891-cd06-49db-929e-dcdd88a9d601", "timestamp": "2025-10-15T08:37:52.295601", "client_ip": "10.200.0.1", "endpoint": "/api/metadata/STYR/DCPO.KHKNDHUR", "error_type": "HTTPException", "error_message": "404: Table not configured", "error_code": "HTTP_404", "additional_context": {"original_detail": "Table not configured"}}
2025-10-15 08:38:09 | ERROR | {"request_id": "82bad980-290b-4200-acbc-70c37d4ed772", "timestamp": "2025-10-15T08:38:09.753360", "client_ip": "10.200.0.1", "endpoint": "/api/metadata/save-extended", "error_type": "RequestValidationError", "error_message": "[{'type': 'json_invalid', 'loc': ('body', 277), 'msg': 'JSON decode error', 'input': {}, 'ctx': {'error': 'Expecting value'}}]", "error_code": "VALIDATION_ERROR", "additional_context": {"validation_errors": [{"field": "277", "message": "JSON decode error", "type": "json_invalid"}]}}
2025-10-15 08:38:09 | ERROR | {"request_id": "82bad980-290b-4200-acbc-70c37d4ed772", "timestamp": "2025-10-15T08:38:09.946277", "client_ip": "10.200.0.1", "endpoint": "/api/metadata/save-extended", "error_type": "AttributeError", "error_message": "'RequestValidationError' object has no attribute 'status_code'", "error_code": "INTERNAL_ERROR", "additional_context": {"traceback": "  + Exception Group Traceback (most recent call last):\n  |   File \"C:\\service-gateway\\venv\\Lib\\site-packages\\starlette\\_utils.py\", line 79, in collapse_excgroups\n  |     yield\n  |   File \"C:\\service-gateway\\venv\\Lib\\site-packages\\starlette\\middleware\\base.py\", line 183, in __call__\n  |     async with anyio.create_task_group() as task_group:\n  |                ~~~~~~~~~~~~~~~~~~~~~~~^^\n  |   File \"C:\\service-gateway\\venv\\Lib\\site-packages\\anyio\\_backends\\_asyncio.py\", line 781, in __aexit__\n  |     raise BaseExceptionGroup(\n  |         \"unhandled errors in a TaskGroup\", self._exceptions\n  |     ) from None\n  | ExceptionGroup: unhandled errors in a TaskGroup (1 sub-exception)\n  +-+---------------- 1 ----------------\n    | Traceback (most recent call last):\n    |   File \"C:\\service-gateway\\venv\\Lib\\site-packages\\starlette\\middleware\\errors.py\", line 164, in __call__\n    |     await self.app(scope, receive, _send)\n    |   File \"C:\\service-gateway\\venv\\Lib\\site-packages\\starlette\\middleware\\cors.py\", line 85, in __call__\n    |     await self.app(scope, receive, send)\n    |   File \"C:\\service-gateway\\venv\\Lib\\site-packages\\starlette\\middleware\\base.py\", line 182, in __call__\n    |     with recv_stream, send_stream, collapse_excgroups():\n    |                                    ~~~~~~~~~~~~~~~~~~^^\n    |   File \"C:\\Python313\\Lib\\contextlib.py\", line 162, in __exit__\n    |     self.gen.throw(value)\n    |     ~~~~~~~~~~~~~~^^^^^^^\n    |   File \"C:\\service-gateway\\venv\\Lib\\site-packages\\starlette\\_utils.py\", line 85, in collapse_excgroups\n    |     raise exc\n    |   File \"C:\\service-gateway\\venv\\Lib\\site-packages\\starlette\\middleware\\base.py\", line 184, in __call__\n    |     response = await self.dispatch_func(request, call_next)\n    |                ^^^^^^^^^^^^^^^^^^^^^^^^^^^^^^^^^^^^^^^^^^^^\n    |   File \"C:\\service-gateway\\utils\\request_middleware.py\", line 15, in dispatch\n    |     response = await call_next(request)\n    |                ^^^^^^^^^^^^^^^^^^^^^^^^\n    |   File \"C:\\service-gateway\\venv\\Lib\\site-packages\\starlette\\middleware\\base.py\", line 159, in call_next\n    |     raise app_exc\n    |   File \"C:\\service-gateway\\venv\\Lib\\site-packages\\starlette\\middleware\\base.py\", line 144, in coro\n    |     await self.app(scope, receive_or_disconnect, send_no_error)\n    |   File \"C:\\service-gateway\\venv\\Lib\\site-packages\\starlette\\middleware\\exceptions.py\", line 63, in __call__\n    |     await wrap_app_handling_exceptions(self.app, conn)(scope, receive, send)\n    |   File \"C:\\service-gateway\\venv\\Lib\\site-packages\\starlette\\_exception_handler.py\", line 53, in wrapped_app\n    |     raise exc\n    |   File \"C:\\service-gateway\\venv\\Lib\\site-packages\\starlette\\_exception_handler.py\", line 42, in wrapped_app\n    |     await app(scope, receive, sender)\n    |   File \"C:\\service-gateway\\venv\\Lib\\site-packages\\starlette\\routing.py\", line 716, in __call__\n    |     await self.middleware_stack(scope, receive, send)\n    |   File \"C:\\service-gateway\\venv\\Lib\\site-packages\\starlette\\routing.py\", line 736, in app\n    |     await route.handle(scope, receive, send)\n    |   File \"C:\\service-gateway\\venv\\Lib\\site-packages\\starlette\\routing.py\", line 290, in handle\n    |     await self.app(scope, receive, send)\n    |   File \"C:\\service-gateway\\venv\\Lib\\site-packages\\starlette\\routing.py\", line 78, in app\n    |     await wrap_app_handling_exceptions(app, request)(scope, receive, send)\n    |   File \"C:\\service-gateway\\venv\\Lib\\site-packages\\starlette\\_exception_handler.py\", line 59, in wrapped_app\n    |     response = await handler(conn, exc)\n    |                ^^^^^^^^^^^^^^^^^^^^^^^^\n    |   File \"C:\\service-gateway\\utils\\error_handler.py\", line 100, in validation_exception_handler\n    |     status_code=exc.status_code,\n    |                 ^^^^^^^^^^^^^^^\n    | AttributeError: 'RequestValidationError' object has no attribute 'status_code'\n    +------------------------------------\n\nDuring handling of the above exception, another exception occurred:\n\nTraceback (most recent call last):\n  File \"C:\\service-gateway\\venv\\Lib\\site-packages\\starlette\\middleware\\errors.py\", line 164, in __call__\n    await self.app(scope, receive, _send)\n  File \"C:\\service-gateway\\venv\\Lib\\site-packages\\starlette\\middleware\\cors.py\", line 85, in __call__\n    await self.app(scope, receive, send)\n  File \"C:\\service-gateway\\venv\\Lib\\site-packages\\starlette\\middleware\\base.py\", line 182, in __call__\n    with recv_stream, send_stream, collapse_excgroups():\n                                   ~~~~~~~~~~~~~~~~~~^^\n  File \"C:\\Python313\\Lib\\contextlib.py\", line 162, in __exit__\n    self.gen.throw(value)\n    ~~~~~~~~~~~~~~^^^^^^^\n  File \"C:\\service-gateway\\venv\\Lib\\site-packages\\starlette\\_utils.py\", line 85, in collapse_excgroups\n    raise exc\n  File \"C:\\service-gateway\\venv\\Lib\\site-packages\\starlette\\middleware\\base.py\", line 184, in __call__\n    response = await self.dispatch_func(request, call_next)\n               ^^^^^^^^^^^^^^^^^^^^^^^^^^^^^^^^^^^^^^^^^^^^\n  File \"C:\\service-gateway\\utils\\request_middleware.py\", line 15, in dispatch\n    response = await call_next(request)\n               ^^^^^^^^^^^^^^^^^^^^^^^^\n  File \"C:\\service-gateway\\venv\\Lib\\site-packages\\starlette\\middleware\\base.py\", line 159, in call_next\n    raise app_exc\n  File \"C:\\service-gateway\\venv\\Lib\\site-packages\\starlette\\middleware\\base.py\", line 144, in coro\n    await self.app(scope, receive_or_disconnect, send_no_error)\n  File \"C:\\service-gateway\\venv\\Lib\\site-packages\\starlette\\middleware\\exceptions.py\", line 63, in __call__\n    await wrap_app_handling_exceptions(self.app, conn)(scope, receive, send)\n  File \"C:\\service-gateway\\venv\\Lib\\site-packages\\starlette\\_exception_handler.py\", line 53, in wrapped_app\n    raise exc\n  File \"C:\\service-gateway\\venv\\Lib\\site-packages\\starlette\\_exception_handler.py\", line 42, in wrapped_app\n    await app(scope, receive, sender)\n  File \"C:\\service-gateway\\venv\\Lib\\site-packages\\starlette\\routing.py\", line 716, in __call__\n    await self.middleware_stack(scope, receive, send)\n  File \"C:\\service-gateway\\venv\\Lib\\site-packages\\starlette\\routing.py\", line 736, in app\n    await route.handle(scope, receive, send)\n  File \"C:\\service-gateway\\venv\\Lib\\site-packages\\starlette\\routing.py\", line 290, in handle\n    await self.app(scope, receive, send)\n  File \"C:\\service-gateway\\venv\\Lib\\site-packages\\starlette\\routing.py\", line 78, in app\n    await wrap_app_handling_exceptions(app, request)(scope, receive, send)\n  File \"C:\\service-gateway\\venv\\Lib\\site-packages\\starlette\\_exception_handler.py\", line 59, in wrapped_app\n    response = await handler(conn, exc)\n               ^^^^^^^^^^^^^^^^^^^^^^^^\n  File \"C:\\service-gateway\\utils\\error_handler.py\", line 100, in validation_exception_handler\n    status_code=exc.status_code,\n                ^^^^^^^^^^^^^^^\nAttributeError: 'RequestValidationError' object has no attribute 'status_code'\n", "exception_type": "AttributeError"}}
2025-10-15 16:11:10 | ERROR | {"request_id": "5c804233-5f6e-47c6-a624-fa72e655bdc5", "timestamp": "2025-10-15T16:11:10.012162", "client_ip": "10.200.0.1", "endpoint": "/api/execute-query", "error_type": "HTTPException", "error_message": "401: Invalid user", "error_code": "HTTP_401", "additional_context": {"original_detail": "Invalid user"}}
2025-10-16 08:29:37 | ERROR | {"request_id": "85e8e70a-143f-4adf-878d-f8a3a2cabbb0", "timestamp": "2025-10-16T08:29:37.169369", "client_ip": "10.200.0.1", "endpoint": "/api/permission-requests/33/deny", "error_type": "AttributeError", "error_message": "'AuditLogger' object has no attribute 'error'", "error_code": "INTERNAL_ERROR", "additional_context": {"traceback": "  + Exception Group Traceback (most recent call last):\n  |   File \"C:\\service-gateway\\venv\\Lib\\site-packages\\starlette\\_utils.py\", line 79, in collapse_excgroups\n  |     yield\n  |   File \"C:\\service-gateway\\venv\\Lib\\site-packages\\starlette\\middleware\\base.py\", line 183, in __call__\n  |     async with anyio.create_task_group() as task_group:\n  |                ~~~~~~~~~~~~~~~~~~~~~~~^^\n  |   File \"C:\\service-gateway\\venv\\Lib\\site-packages\\anyio\\_backends\\_asyncio.py\", line 781, in __aexit__\n  |     raise BaseExceptionGroup(\n  |         \"unhandled errors in a TaskGroup\", self._exceptions\n  |     ) from None\n  | ExceptionGroup: unhandled errors in a TaskGroup (1 sub-exception)\n  +-+---------------- 1 ----------------\n    | Traceback (most recent call last):\n    |   File \"C:\\service-gateway\\venv\\Lib\\site-packages\\starlette\\middleware\\errors.py\", line 164, in __call__\n    |     await self.app(scope, receive, _send)\n    |   File \"C:\\service-gateway\\venv\\Lib\\site-packages\\starlette\\middleware\\cors.py\", line 85, in __call__\n    |     await self.app(scope, receive, send)\n    |   File \"C:\\service-gateway\\venv\\Lib\\site-packages\\starlette\\middleware\\base.py\", line 182, in __call__\n    |     with recv_stream, send_stream, collapse_excgroups():\n    |                                    ~~~~~~~~~~~~~~~~~~^^\n    |   File \"C:\\Python313\\Lib\\contextlib.py\", line 162, in __exit__\n    |     self.gen.throw(value)\n    |     ~~~~~~~~~~~~~~^^^^^^^\n    |   File \"C:\\service-gateway\\venv\\Lib\\site-packages\\starlette\\_utils.py\", line 85, in collapse_excgroups\n    |     raise exc\n    |   File \"C:\\service-gateway\\venv\\Lib\\site-packages\\starlette\\middleware\\base.py\", line 184, in __call__\n    |     response = await self.dispatch_func(request, call_next)\n    |                ^^^^^^^^^^^^^^^^^^^^^^^^^^^^^^^^^^^^^^^^^^^^\n    |   File \"C:\\service-gateway\\utils\\request_middleware.py\", line 15, in dispatch\n    |     response = await call_next(request)\n    |                ^^^^^^^^^^^^^^^^^^^^^^^^\n    |   File \"C:\\service-gateway\\venv\\Lib\\site-packages\\starlette\\middleware\\base.py\", line 159, in call_next\n    |     raise app_exc\n    |   File \"C:\\service-gateway\\venv\\Lib\\site-packages\\starlette\\middleware\\base.py\", line 144, in coro\n    |     await self.app(scope, receive_or_disconnect, send_no_error)\n    |   File \"C:\\service-gateway\\venv\\Lib\\site-packages\\starlette\\middleware\\exceptions.py\", line 63, in __call__\n    |     await wrap_app_handling_exceptions(self.app, conn)(scope, receive, send)\n    |   File \"C:\\service-gateway\\venv\\Lib\\site-packages\\starlette\\_exception_handler.py\", line 53, in wrapped_app\n    |     raise exc\n    |   File \"C:\\service-gateway\\venv\\Lib\\site-packages\\starlette\\_exception_handler.py\", line 42, in wrapped_app\n    |     await app(scope, receive, sender)\n    |   File \"C:\\service-gateway\\venv\\Lib\\site-packages\\starlette\\routing.py\", line 716, in __call__\n    |     await self.middleware_stack(scope, receive, send)\n    |   File \"C:\\service-gateway\\venv\\Lib\\site-packages\\starlette\\routing.py\", line 736, in app\n    |     await route.handle(scope, receive, send)\n    |   File \"C:\\service-gateway\\venv\\Lib\\site-packages\\starlette\\routing.py\", line 290, in handle\n    |     await self.app(scope, receive, send)\n    |   File \"C:\\service-gateway\\venv\\Lib\\site-packages\\starlette\\routing.py\", line 78, in app\n    |     await wrap_app_handling_exceptions(app, request)(scope, receive, send)\n    |   File \"C:\\service-gateway\\venv\\Lib\\site-packages\\starlette\\_exception_handler.py\", line 59, in wrapped_app\n    |     response = await handler(conn, exc)\n    |                ^^^^^^^^^^^^^^^^^^^^^^^^\n    |   File \"C:\\service-gateway\\utils\\error_handler.py\", line 119, in validation_exception_handler\n    |     audit_logger.error(json.dumps({\n    |     ^^^^^^^^^^^^^^^^^^\n    | AttributeError: 'AuditLogger' object has no attribute 'error'\n    +------------------------------------\n\nDuring handling of the above exception, another exception occurred:\n\nTraceback (most recent call last):\n  File \"C:\\service-gateway\\venv\\Lib\\site-packages\\starlette\\middleware\\errors.py\", line 164, in __call__\n    await self.app(scope, receive, _send)\n  File \"C:\\service-gateway\\venv\\Lib\\site-packages\\starlette\\middleware\\cors.py\", line 85, in __call__\n    await self.app(scope, receive, send)\n  File \"C:\\service-gateway\\venv\\Lib\\site-packages\\starlette\\middleware\\base.py\", line 182, in __call__\n    with recv_stream, send_stream, collapse_excgroups():\n                                   ~~~~~~~~~~~~~~~~~~^^\n  File \"C:\\Python313\\Lib\\contextlib.py\", line 162, in __exit__\n    self.gen.throw(value)\n    ~~~~~~~~~~~~~~^^^^^^^\n  File \"C:\\service-gateway\\venv\\Lib\\site-packages\\starlette\\_utils.py\", line 85, in collapse_excgroups\n    raise exc\n  File \"C:\\service-gateway\\venv\\Lib\\site-packages\\starlette\\middleware\\base.py\", line 184, in __call__\n    response = await self.dispatch_func(request, call_next)\n               ^^^^^^^^^^^^^^^^^^^^^^^^^^^^^^^^^^^^^^^^^^^^\n  File \"C:\\service-gateway\\utils\\request_middleware.py\", line 15, in dispatch\n    response = await call_next(request)\n               ^^^^^^^^^^^^^^^^^^^^^^^^\n  File \"C:\\service-gateway\\venv\\Lib\\site-packages\\starlette\\middleware\\base.py\", line 159, in call_next\n    raise app_exc\n  File \"C:\\service-gateway\\venv\\Lib\\site-packages\\starlette\\middleware\\base.py\", line 144, in coro\n    await self.app(scope, receive_or_disconnect, send_no_error)\n  File \"C:\\service-gateway\\venv\\Lib\\site-packages\\starlette\\middleware\\exceptions.py\", line 63, in __call__\n    await wrap_app_handling_exceptions(self.app, conn)(scope, receive, send)\n  File \"C:\\service-gateway\\venv\\Lib\\site-packages\\starlette\\_exception_handler.py\", line 53, in wrapped_app\n    raise exc\n  File \"C:\\service-gateway\\venv\\Lib\\site-packages\\starlette\\_exception_handler.py\", line 42, in wrapped_app\n    await app(scope, receive, sender)\n  File \"C:\\service-gateway\\venv\\Lib\\site-packages\\starlette\\routing.py\", line 716, in __call__\n    await self.middleware_stack(scope, receive, send)\n  File \"C:\\service-gateway\\venv\\Lib\\site-packages\\starlette\\routing.py\", line 736, in app\n    await route.handle(scope, receive, send)\n  File \"C:\\service-gateway\\venv\\Lib\\site-packages\\starlette\\routing.py\", line 290, in handle\n    await self.app(scope, receive, send)\n  File \"C:\\service-gateway\\venv\\Lib\\site-packages\\starlette\\routing.py\", line 78, in app\n    await wrap_app_handling_exceptions(app, request)(scope, receive, send)\n  File \"C:\\service-gateway\\venv\\Lib\\site-packages\\starlette\\_exception_handler.py\", line 59, in wrapped_app\n    response = await handler(conn, exc)\n               ^^^^^^^^^^^^^^^^^^^^^^^^\n  File \"C:\\service-gateway\\utils\\error_handler.py\", line 119, in validation_exception_handler\n    audit_logger.error(json.dumps({\n    ^^^^^^^^^^^^^^^^^^\nAttributeError: 'AuditLogger' object has no attribute 'error'\n", "exception_type": "AttributeError"}}
2025-10-16 08:29:44 | ERROR | {"request_id": "0ce3ce0f-de7a-433e-8c78-a6d1d1aa88f6", "timestamp": "2025-10-16T08:29:44.891795", "client_ip": "10.200.0.1", "endpoint": "/api/permission-requests/33/deny", "error_type": "AttributeError", "error_message": "'AuditLogger' object has no attribute 'error'", "error_code": "INTERNAL_ERROR", "additional_context": {"traceback": "  + Exception Group Traceback (most recent call last):\n  |   File \"C:\\service-gateway\\venv\\Lib\\site-packages\\starlette\\_utils.py\", line 79, in collapse_excgroups\n  |     yield\n  |   File \"C:\\service-gateway\\venv\\Lib\\site-packages\\starlette\\middleware\\base.py\", line 183, in __call__\n  |     async with anyio.create_task_group() as task_group:\n  |                ~~~~~~~~~~~~~~~~~~~~~~~^^\n  |   File \"C:\\service-gateway\\venv\\Lib\\site-packages\\anyio\\_backends\\_asyncio.py\", line 781, in __aexit__\n  |     raise BaseExceptionGroup(\n  |         \"unhandled errors in a TaskGroup\", self._exceptions\n  |     ) from None\n  | ExceptionGroup: unhandled errors in a TaskGroup (1 sub-exception)\n  +-+---------------- 1 ----------------\n    | Traceback (most recent call last):\n    |   File \"C:\\service-gateway\\venv\\Lib\\site-packages\\starlette\\middleware\\errors.py\", line 164, in __call__\n    |     await self.app(scope, receive, _send)\n    |   File \"C:\\service-gateway\\venv\\Lib\\site-packages\\starlette\\middleware\\cors.py\", line 85, in __call__\n    |     await self.app(scope, receive, send)\n    |   File \"C:\\service-gateway\\venv\\Lib\\site-packages\\starlette\\middleware\\base.py\", line 182, in __call__\n    |     with recv_stream, send_stream, collapse_excgroups():\n    |                                    ~~~~~~~~~~~~~~~~~~^^\n    |   File \"C:\\Python313\\Lib\\contextlib.py\", line 162, in __exit__\n    |     self.gen.throw(value)\n    |     ~~~~~~~~~~~~~~^^^^^^^\n    |   File \"C:\\service-gateway\\venv\\Lib\\site-packages\\starlette\\_utils.py\", line 85, in collapse_excgroups\n    |     raise exc\n    |   File \"C:\\service-gateway\\venv\\Lib\\site-packages\\starlette\\middleware\\base.py\", line 184, in __call__\n    |     response = await self.dispatch_func(request, call_next)\n    |                ^^^^^^^^^^^^^^^^^^^^^^^^^^^^^^^^^^^^^^^^^^^^\n    |   File \"C:\\service-gateway\\utils\\request_middleware.py\", line 15, in dispatch\n    |     response = await call_next(request)\n    |                ^^^^^^^^^^^^^^^^^^^^^^^^\n    |   File \"C:\\service-gateway\\venv\\Lib\\site-packages\\starlette\\middleware\\base.py\", line 159, in call_next\n    |     raise app_exc\n    |   File \"C:\\service-gateway\\venv\\Lib\\site-packages\\starlette\\middleware\\base.py\", line 144, in coro\n    |     await self.app(scope, receive_or_disconnect, send_no_error)\n    |   File \"C:\\service-gateway\\venv\\Lib\\site-packages\\starlette\\middleware\\exceptions.py\", line 63, in __call__\n    |     await wrap_app_handling_exceptions(self.app, conn)(scope, receive, send)\n    |   File \"C:\\service-gateway\\venv\\Lib\\site-packages\\starlette\\_exception_handler.py\", line 53, in wrapped_app\n    |     raise exc\n    |   File \"C:\\service-gateway\\venv\\Lib\\site-packages\\starlette\\_exception_handler.py\", line 42, in wrapped_app\n    |     await app(scope, receive, sender)\n    |   File \"C:\\service-gateway\\venv\\Lib\\site-packages\\starlette\\routing.py\", line 716, in __call__\n    |     await self.middleware_stack(scope, receive, send)\n    |   File \"C:\\service-gateway\\venv\\Lib\\site-packages\\starlette\\routing.py\", line 736, in app\n    |     await route.handle(scope, receive, send)\n    |   File \"C:\\service-gateway\\venv\\Lib\\site-packages\\starlette\\routing.py\", line 290, in handle\n    |     await self.app(scope, receive, send)\n    |   File \"C:\\service-gateway\\venv\\Lib\\site-packages\\starlette\\routing.py\", line 78, in app\n    |     await wrap_app_handling_exceptions(app, request)(scope, receive, send)\n    |   File \"C:\\service-gateway\\venv\\Lib\\site-packages\\starlette\\_exception_handler.py\", line 59, in wrapped_app\n    |     response = await handler(conn, exc)\n    |                ^^^^^^^^^^^^^^^^^^^^^^^^\n    |   File \"C:\\service-gateway\\utils\\error_handler.py\", line 119, in validation_exception_handler\n    |     audit_logger.error(json.dumps({\n    |     ^^^^^^^^^^^^^^^^^^\n    | AttributeError: 'AuditLogger' object has no attribute 'error'\n    +------------------------------------\n\nDuring handling of the above exception, another exception occurred:\n\nTraceback (most recent call last):\n  File \"C:\\service-gateway\\venv\\Lib\\site-packages\\starlette\\middleware\\errors.py\", line 164, in __call__\n    await self.app(scope, receive, _send)\n  File \"C:\\service-gateway\\venv\\Lib\\site-packages\\starlette\\middleware\\cors.py\", line 85, in __call__\n    await self.app(scope, receive, send)\n  File \"C:\\service-gateway\\venv\\Lib\\site-packages\\starlette\\middleware\\base.py\", line 182, in __call__\n    with recv_stream, send_stream, collapse_excgroups():\n                                   ~~~~~~~~~~~~~~~~~~^^\n  File \"C:\\Python313\\Lib\\contextlib.py\", line 162, in __exit__\n    self.gen.throw(value)\n    ~~~~~~~~~~~~~~^^^^^^^\n  File \"C:\\service-gateway\\venv\\Lib\\site-packages\\starlette\\_utils.py\", line 85, in collapse_excgroups\n    raise exc\n  File \"C:\\service-gateway\\venv\\Lib\\site-packages\\starlette\\middleware\\base.py\", line 184, in __call__\n    response = await self.dispatch_func(request, call_next)\n               ^^^^^^^^^^^^^^^^^^^^^^^^^^^^^^^^^^^^^^^^^^^^\n  File \"C:\\service-gateway\\utils\\request_middleware.py\", line 15, in dispatch\n    response = await call_next(request)\n               ^^^^^^^^^^^^^^^^^^^^^^^^\n  File \"C:\\service-gateway\\venv\\Lib\\site-packages\\starlette\\middleware\\base.py\", line 159, in call_next\n    raise app_exc\n  File \"C:\\service-gateway\\venv\\Lib\\site-packages\\starlette\\middleware\\base.py\", line 144, in coro\n    await self.app(scope, receive_or_disconnect, send_no_error)\n  File \"C:\\service-gateway\\venv\\Lib\\site-packages\\starlette\\middleware\\exceptions.py\", line 63, in __call__\n    await wrap_app_handling_exceptions(self.app, conn)(scope, receive, send)\n  File \"C:\\service-gateway\\venv\\Lib\\site-packages\\starlette\\_exception_handler.py\", line 53, in wrapped_app\n    raise exc\n  File \"C:\\service-gateway\\venv\\Lib\\site-packages\\starlette\\_exception_handler.py\", line 42, in wrapped_app\n    await app(scope, receive, sender)\n  File \"C:\\service-gateway\\venv\\Lib\\site-packages\\starlette\\routing.py\", line 716, in __call__\n    await self.middleware_stack(scope, receive, send)\n  File \"C:\\service-gateway\\venv\\Lib\\site-packages\\starlette\\routing.py\", line 736, in app\n    await route.handle(scope, receive, send)\n  File \"C:\\service-gateway\\venv\\Lib\\site-packages\\starlette\\routing.py\", line 290, in handle\n    await self.app(scope, receive, send)\n  File \"C:\\service-gateway\\venv\\Lib\\site-packages\\starlette\\routing.py\", line 78, in app\n    await wrap_app_handling_exceptions(app, request)(scope, receive, send)\n  File \"C:\\service-gateway\\venv\\Lib\\site-packages\\starlette\\_exception_handler.py\", line 59, in wrapped_app\n    response = await handler(conn, exc)\n               ^^^^^^^^^^^^^^^^^^^^^^^^\n  File \"C:\\service-gateway\\utils\\error_handler.py\", line 119, in validation_exception_handler\n    audit_logger.error(json.dumps({\n    ^^^^^^^^^^^^^^^^^^\nAttributeError: 'AuditLogger' object has no attribute 'error'\n", "exception_type": "AttributeError"}}
2025-10-16 12:30:37 | ERROR | {"request_id": "e213041d-265b-4e43-b171-1e1fe8426e18", "timestamp": "2025-10-16T12:30:37.087719", "client_ip": "10.200.0.1", "endpoint": "/api/STYR/schema-with-rbac", "error_type": "RequestValidationError", "error_message": "[{'type': 'missing', 'loc': ('query', 'user_role'), 'msg': 'Field required', 'input': None}]", "error_code": "VALIDATION_ERROR", "additional_context": {"validation_errors": [{"field": "('query', 'user_role')", "message": "Field required", "type": "missing"}]}}
2025-10-16 12:30:45 | ERROR | {"request_id": "4f879914-d53a-4369-aee5-b572c4068ae7", "timestamp": "2025-10-16T12:30:45.927383", "client_ip": "10.200.0.1", "endpoint": "/api/STYR/schema-with-rbac", "error_type": "RequestValidationError", "error_message": "[{'type': 'missing', 'loc': ('query', 'user_role'), 'msg': 'Field required', 'input': None}]", "error_code": "VALIDATION_ERROR", "additional_context": {"validation_errors": [{"field": "('query', 'user_role')", "message": "Field required", "type": "missing"}]}}
2025-10-16 12:31:00 | ERROR | {"request_id": "899eab9e-2b78-48df-9179-611259ba5604", "timestamp": "2025-10-16T12:31:00.062805", "client_ip": "10.200.0.1", "endpoint": "/api/STYR/schema-with-rbac", "error_type": "RequestValidationError", "error_message": "[{'type': 'missing', 'loc': ('query', 'user_role'), 'msg': 'Field required', 'input': None}]", "error_code": "VALIDATION_ERROR", "additional_context": {"validation_errors": [{"field": "('query', 'user_role')", "message": "Field required", "type": "missing"}]}}
2025-10-16 12:31:15 | ERROR | {"request_id": "578b5e4e-25e9-4395-bd84-02a752e5d133", "timestamp": "2025-10-16T12:31:15.295047", "client_ip": "10.200.0.1", "endpoint": "/api/STYR/schema-with-rbac", "error_type": "RequestValidationError", "error_message": "[{'type': 'missing', 'loc': ('query', 'user_role'), 'msg': 'Field required', 'input': None}]", "error_code": "VALIDATION_ERROR", "additional_context": {"validation_errors": [{"field": "('query', 'user_role')", "message": "Field required", "type": "missing"}]}}
2025-10-16 12:34:06 | ERROR | {"request_id": "a6bcb403-55e4-4944-ad74-7842496d49a1", "timestamp": "2025-10-16T12:34:06.046058", "client_ip": "10.200.0.1", "endpoint": "/api/execute-query", "error_type": "HTTPException", "error_message": "403: Access denied to table DCPO.AUTHOR_ARTICLE. Permission request #60 created.", "error_code": "HTTP_403", "additional_context": {"original_detail": "Access denied to table DCPO.AUTHOR_ARTICLE. Permission request #60 created."}}
2025-10-16 12:34:45 | ERROR | {"request_id": "1c2ce7ca-338c-4230-97f5-f476c85ec3ed", "timestamp": "2025-10-16T12:34:45.297966", "client_ip": "10.200.0.1", "endpoint": "/api/execute-query", "error_type": "HTTPException", "error_message": "403: Access denied to table DCPO.ARTPUBLI. Permission request #61 created.", "error_code": "HTTP_403", "additional_context": {"original_detail": "Access denied to table DCPO.ARTPUBLI. Permission request #61 created."}}
2025-10-16 12:35:17 | ERROR | {"request_id": "0684c524-7775-4c58-baf2-6c7c490323f3", "timestamp": "2025-10-16T12:35:17.021468", "client_ip": "10.200.0.1", "endpoint": "/api/STYR/schema-with-rbac", "error_type": "RequestValidationError", "error_message": "[{'type': 'missing', 'loc': ('query', 'user_role'), 'msg': 'Field required', 'input': None}]", "error_code": "VALIDATION_ERROR", "additional_context": {"validation_errors": [{"field": "('query', 'user_role')", "message": "Field required", "type": "missing"}]}}
2025-10-16 12:35:23 | ERROR | {"request_id": "f42ab128-80e2-4e4c-9c9d-93888a2fc940", "timestamp": "2025-10-16T12:35:23.950669", "client_ip": "10.200.0.1", "endpoint": "/api/STYR/schema-with-rbac", "error_type": "RequestValidationError", "error_message": "[{'type': 'missing', 'loc': ('query', 'user_role'), 'msg': 'Field required', 'input': None}]", "error_code": "VALIDATION_ERROR", "additional_context": {"validation_errors": [{"field": "('query', 'user_role')", "message": "Field required", "type": "missing"}]}}
2025-10-16 12:35:37 | ERROR | {"request_id": "bbf4fda1-cb5d-466f-b4cb-0bce39e7ff73", "timestamp": "2025-10-16T12:35:37.219930", "client_ip": "10.200.0.1", "endpoint": "/api/STYR/schema-with-rbac", "error_type": "RequestValidationError", "error_message": "[{'type': 'missing', 'loc': ('query', 'user_role'), 'msg': 'Field required', 'input': None}]", "error_code": "VALIDATION_ERROR", "additional_context": {"validation_errors": [{"field": "('query', 'user_role')", "message": "Field required", "type": "missing"}]}}
2025-10-16 12:57:16 | ERROR | {"request_id": "2803468c-ff1d-47b3-8937-a7f2c4df0fa5", "timestamp": "2025-10-16T12:57:16.623043", "client_ip": "10.200.0.1", "endpoint": "/api/execute-query", "error_type": "HTTPException", "error_message": "401: Invalid user", "error_code": "HTTP_401", "additional_context": {"original_detail": "Invalid user"}}
2025-10-16 12:57:28 | ERROR | {"request_id": "0dd9456f-97eb-4b0e-953e-9bbe7f09808e", "timestamp": "2025-10-16T12:57:28.779097", "client_ip": "10.200.0.1", "endpoint": "/api/execute-query", "error_type": "HTTPException", "error_message": "401: Invalid user", "error_code": "HTTP_401", "additional_context": {"original_detail": "Invalid user"}}
